Workbook

Sheet График поставки
B2: График поставки арматурных каркасов для буронабивных свай на объект МАЙСКАЯ ВЭС
B3: ПОСТАВЩИК: ООО "НЕФТЕБИТУМСЕРВИС - ВОЛГА"
B5: ИСПЫТУЕМЫЕ БНС | D5: ПЛАН | G5: ДАТА ПОСТАВКИ | DH5: ИТОГО
G6: 46174 | CS6: 46204
D7: Кол-во каркасов | G7: 01 | J7: 02 | M7: 03 | P7: 04 | S7: 05 | V7: 06 | Y7: 07 | AB7: 08 | AE7: 09 | AH7: 10 | AK7: 11 | AN7: 12 | AQ7: 13 | AT7: 14 | AW7: 15 | AZ7: 16 | BC7: 17 | BF7: 18 | BI7: 19 | BL7: 20 | BO7: 21 | BR7: 22 | BU7: 23 | BX7: 24 | CA7: 25 | CD7: 26 | CG7: 27 | CJ7: 28 | CM7: 29 | CP7: 30 | CS7: 01 | CV7: 02 | CY7: 03 | DB7: 04 | DE7: 05
B8: №ВЭУ | C8: кол-во свай | D8: КП-1 | E8: КП-2 | F8: КП-3 | G8: КП-1 | H8: КП-2 | I8: КП-3 | J8: КП-1 | K8: КП-2 | L8: КП-3 | M8: КП-1 | N8: КП-2 | O8: КП-3 | P8: КП-1 | Q8: КП-2 | R8: КП-3 | S8: КП-1 | T8: КП-2 | U8: КП-3 | V8: КП-1 | W8: КП-2 | X8: КП-3 | Y8: КП-1 | Z8: КП-2 | AA8: КП-3 | AB8: КП-1 | AC8: КП-2 | AD8: КП-3 | AE8: КП-1 | AF8: КП-2 | AG8: КП-3 | AH8: КП-1 | AI8: КП-2 | AJ8: КП-3 | AK8: КП-1 | AL8: КП-2 | AM8: КП-3 | AN8: КП-1 | AO8: КП-2 | AP8: КП-3 | AQ8: КП-1 | AR8: КП-2 | AS8: КП-3 | AT8: КП-1 | AU8: КП-2 | AV8: КП-3 | AW8: КП-1 | AX8: КП-2 | AY8: КП-3 | AZ8: КП-1 | BA8: КП-2 | BB8: КП-3 | BC8: КП-1 | BD8: КП-2 | BE8: КП-3 | BF8: КП-1 | BG8: КП-2 | BH8: КП-3 | BI8: КП-1 | BJ8: КП-2 | BK8: КП-3 | BL8: КП-1 | BM8: КП-2 | BN8: КП-3 | BO8: КП-1 | BP8: КП-2 | BQ8: КП-3 | BR8: КП-1 | BS8: КП-2 | BT8: КП-3 | BU8: КП-1 | BV8: КП-2 | BW8: КП-3 | BX8: КП-1 | BY8: КП-2 | BZ8: КП-3 | CA8: КП-1 | CB8: КП-2 | CC8: КП-3 | CD8: КП-1 | CE8: КП-2 | CF8: КП-3 | CG8: КП-1 | CH8: КП-2 | CI8: КП-3 | CJ8: КП-1 | CK8: КП-2 | CL8: КП-3 | CM8: КП-1 | CN8: КП-2 | CO8: КП-3 | CP8: КП-1 | CQ8: КП-2 | CR8: КП-3 | CS8: КП-1 | CT8: КП-2 | CU8: КП-3 | CV8: КП-1 | CW8: КП-2 | CX8: КП-3 | CY8: КП-1 | CZ8: КП-2 | DA8: КП-3 | DB8: КП-1 | DC8: КП-2 | DD8: КП-3 | DE8: КП-1 | DF8: КП-2 | DG8: КП-3
B9: ВЭУ-2 | C9: 1 | D9: 1 | E9: 1 | F9: 1 | G9: 1 | H9: 1 | I9: 1 | DH9: =SUM(G9:DG9) -> 3
B10: ВЭУ-6 | C10: 1 | D10: 1 | E10: 1 | F10: 1 | G10: 1 | H10: 1 | I10: 1 | DH10: =SUM(G10:DG10) -> 3
B11: ВЭУ-10 | C11: 1 | D11: 1 | E11: 1 | F11: 1 | J11: 1 | K11: 1 | L11: 1 | DH11: =SUM(G11:DG11) -> 3
B12: ВЭУ-15 | C12: 1 | D12: 1 | E12: 1 | F12: 1 | J12: 1 | K12: 1 | L12: 1 | DH12: =SUM(G12:DG12) -> 3
B13: ВЭУ-18 | C13: 1 | D13: 1 | E13: 1 | F13: 1 | M13: 1 | N13: 1 | O13: 1 | DH13: =SUM(G13:DG13) -> 3
B14: ВЭУ-19 | C14: 1 | D14: 1 | E14: 1 | F14: 1 | M14: 1 | N14: 1 | O14: 1 | DH14: =SUM(G14:DG14) -> 3
B15: ВЭУ-20 | C15: 1 | D15: 1 | E15: 1 | F15: 1 | P15: 1 | Q15: 1 | R15: 1 | DH15: =SUM(G15:DG15) -> 3
B16: ВЭУ-22 | C16: 1 | D16: 1 | E16: 1 | F16: 1 | P16: 1 | Q16: 1 | R16: 1 | DH16: =SUM(G16:DG16) -> 3
B17: ВЭУ-25 | C17: 1 | D17: 1 | E17: 1 | F17: 1 | S17: 1 | T17: 1 | U17: 1 | DH17: =SUM(G17:DG17) -> 3
B18: ВЭУ-31 | C18: 1 | D18: 1 | E18: 1 | F18: 1 | S18: 1 | T18: 1 | U18: 1 | DH18: =SUM(G18:DG18) -> 3
B19: ВЭУ-37 | C19: 1 | D19: 1 | E19: 1 | F19: 1 | V19: 1 | W19: 1 | X19: 1 | DH19: =SUM(G19:DG19) -> 3
B20: ВЭУ-38 | C20: 1 | D20: 1 | E20: 1 | F20: 1 | V20: 1 | W20: 1 | X20: 1 | DH20: =SUM(G20:DG20) -> 3
B21: ВЭУ-42 | C21: 1 | D21: 1 | E21: 1 | F21: 1 | Y21: 1 | Z21: 1 | AA21: 1 | DH21: =SUM(G21:DG21) -> 3
B22: ВЭУ-47 | C22: 1 | D22: 1 | E22: 1 | F22: 1 | Y22: 1 | Z22: 1 | AA22: 1 | DH22: =SUM(G22:DG22) -> 3
B23: ВЭУ-48 | C23: 1 | D23: 1 | E23: 1 | F23: 1 | AB23: 1 | AC23: 1 | AD23: 1 | DH23: =SUM(G23:DG23) -> 3
B24: ВЭУ-51 | C24: 1 | D24: 1 | E24: 1 | F24: 1 | AB24: 1 | AC24: 1 | AD24: 1 | DH24: =SUM(G24:DG24) -> 3
B25: ИТОГО | C25: =SUM(C9:C24) -> 16 | D25: =SUM(D9:D24) -> 16 | E25: =SUM(E9:E24) -> 16 | F25: =SUM(F9:F24) -> 16 | G25: =SUM(G9:G24) -> 2 | H25: =SUM(H9:H24) -> 2 | I25: =SUM(I9:I24) -> 2 | J25: =SUM(J9:J24) -> 2 | ... DH25: =SUM(DH9:DH24) -> 48
B26: АНКЕРНЫЕ БНС | D26: ПЛАН | G26: ДАТА ПОСТАВКИ | DH26: ИТОГО
G27: 46174 | CS27: 46204
D28: Кол-во каркасов | G28: 01 | J28: 02 | M28: 03 | P28: 04 | S28: 05 | V28: 06 | Y28: 07 | AB28: 08 | AE28: 09 | AH28: 10 | AK28: 11 | AN28: 12 | AQ28: 13 | AT28: 14 | AW28: 15 | AZ28: 16 | BC28: 17 | BF28: 18 | BI28: 19 | BL28: 20 | BO28: 21 | BR28: 22 | BU28: 23 | BX28: 24 | CA28: 25 | CD28: 26 | CG28: 27 | CJ28: 28 | CM28: 29 | CP28: 30 | CS28: 01 | CV28: 02 | CY28: 03 | DB28: 04 | DE28: 05
B29: №ВЭУ | C29: кол-во свай | D29: КП-1 | E29: КП-2 | F29: КП-3 | G29: КП-1 | H29: КП-2 | I29: КП-3 | J29: КП-1 | K29: КП-2 | L29: КП-3 | M29: КП-1 | N29: КП-2 | O29: КП-3 | P29: КП-1 | Q29: КП-2 | R29: КП-3 | S29: КП-1 | T29: КП-2 | U29: КП-3 | V29: КП-1 | W29: КП-2 | X29: КП-3 | Y29: КП-1 | Z29: КП-2 | AA29: КП-3 | AB29: КП-1 | AC29: КП-2 | AD29: КП-3 | AE29: КП-1 | AF29: КП-2 | AG29: КП-3 | AH29: КП-1 | AI29: КП-2 | AJ29: КП-3 | AK29: КП-1 | AL29: КП-2 | AM29: КП-3 | AN29: КП-1 | AO29: КП-2 | AP29: КП-3 | AQ29: КП-1 | AR29: КП-2 | AS29: КП-3 | AT29: КП-1 | AU29: КП-2 | AV29: КП-3 | AW29: КП-1 | AX29: КП-2 | AY29: КП-3 | AZ29: КП-1 | BA29: КП-2 | BB29: КП-3 | BC29: КП-1 | BD29: КП-2 | BE29: КП-3 | BF29: КП-1 | BG29: КП-2 | BH29: КП-3 | BI29: КП-1 | BJ29: КП-2 | BK29: КП-3 | BL29: КП-1 | BM29: КП-2 | BN29: КП-3 | BO29: КП-1 | BP29: КП-2 | BQ29: КП-3 | BR29: КП-1 | BS29: КП-2 | BT29: КП-3 | BU29: КП-1 | BV29: КП-2 | BW29: КП-3 | BX29: КП-1 | BY29: КП-2 | BZ29: КП-3 | CA29: КП-1 | CB29: КП-2 | CC29: КП-3 | CD29: КП-1 | CE29: КП-2 | CF29: КП-3 | CG29: КП-1 | CH29: КП-2 | CI29: КП-3 | CJ29: КП-1 | CK29: КП-2 | CL29: КП-3 | CM29: КП-1 | CN29: КП-2 | CO29: КП-3 | CP29: КП-1 | CQ29: КП-2 | CR29: КП-3 | CS29: КП-1 | CT29: КП-2 | CU29: КП-3 | CV29: КП-1 | CW29: КП-2 | CX29: КП-3 | CY29: КП-1 | CZ29: КП-2 | DA29: КП-3 | DB29: КП-1 | DC29: КП-2 | DD29: КП-3 | DE29: КП-1 | DF29: КП-2 | DG29: КП-3
B30: ВЭУ-2 | C30: 2 | D30: 2 | E30: 2 | F30: 2 | G30: 2 | H30: 2 | I30: 2 | DH30: =SUM(G30:DG30) -> 6
B31: ВЭУ-6 | C31: 2 | D31: 2 | E31: 2 | F31: 2 | G31: 2 | H31: 2 | I31: 2 | DH31: =SUM(G31:DG31) -> 6
B32: ВЭУ-10 | C32: 2 | D32: 2 | E32: 2 | F32: 2 | J32: 2 | K32: 2 | L32: 2 | DH32: =SUM(G32:DG32) -> 6
B33: ВЭУ-15 | C33: 2 | D33: 2 | E33: 2 | F33: 2 | J33: 2 | K33: 2 | L33: 2 | DH33: =SUM(G33:DG33) -> 6
B34: ВЭУ-18 | C34: 2 | D34: 2 | E34: 2 | F34: 2 | M34: 2 | N34: 2 | O34: 2 | DH34: =SUM(G34:DG34) -> 6
B35: ВЭУ-19 | C35: 2 | D35: 2 | E35: 2 | F35: 2 | M35: 2 | N35: 2 | O35: 2 | DH35: =SUM(G35:DG35) -> 6
B36: ВЭУ-20 | C36: 2 | D36: 2 | E36: 2 | F36: 2 | P36: 2 | Q36: 2 | R36: 2 | DH36: =SUM(G36:DG36) -> 6
B37: ВЭУ-22 | C37: 2 | D37: 2 | E37: 2 | F37: 2 | P37: 2 | Q37: 2 | R37: 2 | DH37: =SUM(G37:DG37) -> 6
B38: ВЭУ-25 | C38: 2 | D38: 2 | E38: 2 | F38: 2 | S38: 2 | T38: 2 | U38: 2 | DH38: =SUM(G38:DG38) -> 6
B39: ВЭУ-31 | C39: 2 | D39: 2 | E39: 2 | F39: 2 | S39: 2 | T39: 2 | U39: 2 | DH39: =SUM(G39:DG39) -> 6
B40: ВЭУ-37 | C40: 2 | D40: 2 | E40: 2 | F40: 2 | V40: 2 | W40: 2 | X40: 2 | DH40: =SUM(G40:DG40) -> 6
B41: ВЭУ-38 | C41: 2 | D41: 2 | E41: 2 | F41: 2 | V41: 2 | W41: 2 | X41: 2 | DH41: =SUM(G41:DG41) -> 6
B42: ВЭУ-42 | C42: 2 | D42: 2 | E42: 2 | F42: 2 | Y42: 2 | Z42: 2 | AA42: 2 | DH42: =SUM(G42:DG42) -> 6
...

Sheet График поставки версия 2
B2: График поставки арматурных каркасов для буронабивных свай на объект МАЙСКАЯ ВЭС
B3: ПОСТАВЩИК: ООО "НЕФТЕБИТУМСЕРВИС - ВОЛГА"
B5: ИСПЫТУЕМЫЕ БНС | D5: ПЛАН | G5: ДАТА ПОСТАВКИ | DH5: ИТОГО
G6: 46174 | CS6: 46204
D7: Кол-во каркасов | G7: 01 | J7: 02 | M7: 03 | P7: 04 | S7: 05 | V7: 06 | Y7: 07 | AB7: 08 | AE7: 09 | AH7: 10 | AK7: 11 | AN7: 12 | AQ7: 13 | AT7: 14 | AW7: 15 | AZ7: 16 | BC7: 17 | BF7: 18 | BI7: 19 | BL7: 20 | BO7: 21 | BR7: 22 | BU7: 23 | BX7: 24 | CA7: 25 | CD7: 26 | CG7: 27 | CJ7: 28 | CM7: 29 | CP7: 30 | CS7: 01 | CV7: 02 | CY7: 03 | DB7: 04 | DE7: 05
B8: №ВЭУ | C8: кол-во свай | D8: КП-1 | E8: КП-2 | F8: КП-3 | G8: КП-1 | H8: КП-2 | I8: КП-3 | J8: КП-1 | K8: КП-2 | L8: КП-3 | M8: КП-1 | N8: КП-2 | O8: КП-3 | P8: КП-1 | Q8: КП-2 | R8: КП-3 | S8: КП-1 | T8: КП-2 | U8: КП-3 | V8: КП-1 | W8: КП-2 | X8: КП-3 | Y8: КП-1 | Z8: КП-2 | AA8: КП-3 | AB8: КП-1 | AC8: КП-2 | AD8: КП-3 | AE8: КП-1 | AF8: КП-2 | AG8: КП-3 | AH8: КП-1 | AI8: КП-2 | AJ8: КП-3 | AK8: КП-1 | AL8: КП-2 | AM8: КП-3 | AN8: КП-1 | AO8: КП-2 | AP8: КП-3 | AQ8: КП-1 | AR8: КП-2 | AS8: КП-3 | AT8: КП-1 | AU8: КП-2 | AV8: КП-3 | AW8: КП-1 | AX8: КП-2 | AY8: КП-3 | AZ8: КП-1 | BA8: КП-2 | BB8: КП-3 | BC8: КП-1 | BD8: КП-2 | BE8: КП-3 | BF8: КП-1 | BG8: КП-2 | BH8: КП-3 | BI8: КП-1 | BJ8: КП-2 | BK8: КП-3 | BL8: КП-1 | BM8: КП-2 | BN8: КП-3 | BO8: КП-1 | BP8: КП-2 | BQ8: КП-3 | BR8: КП-1 | BS8: КП-2 | BT8: КП-3 | BU8: КП-1 | BV8: КП-2 | BW8: КП-3 | BX8: КП-1 | BY8: КП-2 | BZ8: КП-3 | CA8: КП-1 | CB8: КП-2 | CC8: КП-3 | CD8: КП-1 | CE8: КП-2 | CF8: КП-3 | CG8: КП-1 | CH8: КП-2 | CI8: КП-3 | CJ8: КП-1 | CK8: КП-2 | CL8: КП-3 | CM8: КП-1 | CN8: КП-2 | CO8: КП-3 | CP8: КП-1 | CQ8: КП-2 | CR8: КП-3 | CS8: КП-1 | CT8: КП-2 | CU8: КП-3 | CV8: КП-1 | CW8: КП-2 | CX8: КП-3 | CY8: КП-1 | CZ8: КП-2 | DA8: КП-3 | DB8: КП-1 | DC8: КП-2 | DD8: КП-3 | DE8: КП-1 | DF8: КП-2 | DG8: КП-3
B9: ВЭУ-2 | C9: 1 | D9: 1 | E9: 1 | F9: 1 | G9: 1 | H9: 1 | I9: 1 | DH9: =SUM(G9:DG9) -> 3
B10: ВЭУ-6 | C10: 1 | D10: 1 | E10: 1 | F10: 1 | G10: 1 | H10: 1 | I10: 1 | DH10: =SUM(G10:DG10) -> 3
B11: ВЭУ-10 | C11: 1 | D11: 1 | E11: 1 | F11: 1 | J11: 1 | K11: 1 | L11: 1 | DH11: =SUM(G11:DG11) -> 3
B12: ВЭУ-15 | C12: 1 | D12: 1 | E12: 1 | F12: 1 | J12: 1 | K12: 1 | L12: 1 | DH12: =SUM(G12:DG12) -> 3
B13: ВЭУ-18 | C13: 1 | D13: 1 | E13: 1 | F13: 1 | M13: 1 | N13: 1 | O13: 1 | DH13: =SUM(G13:DG13) -> 3
B14: ВЭУ-19 | C14: 1 | D14: 1 | E14: 1 | F14: 1 | M14: 1 | N14: 1 | O14: 1 | DH14: =SUM(G14:DG14) -> 3
B15: ВЭУ-20 | C15: 1 | D15: 1 | E15: 1 | F15: 1 | P15: 1 | Q15: 1 | R15: 1 | DH15: =SUM(G15:DG15) -> 3
B16: ВЭУ-22 | C16: 1 | D16: 1 | E16: 1 | F16: 1 | AZ16: 1 | BA16: 1 | BB16: 1 | DH16: =SUM(G16:DG16) -> 3
B17: ВЭУ-25 | C17: 1 | D17: 1 | E17: 1 | F17: 1 | AZ17: 1 | BA17: 1 | BB17: 1 | DH17: =SUM(G17:DG17) -> 3
B18: ВЭУ-31 | C18: 1 | D18: 1 | E18: 1 | F18: 1 | BC18: 1 | BD18: 1 | BE18: 1 | DH18: =SUM(G18:DG18) -> 3
B19: ВЭУ-37 | C19: 1 | D19: 1 | E19: 1 | F19: 1 | BC19: 1 | BD19: 1 | BE19: 1 | DH19: =SUM(G19:DG19) -> 3
B20: ВЭУ-38 | C20: 1 | D20: 1 | E20: 1 | F20: 1 | BF20: 1 | BG20: 1 | BH20: 1 | DH20: =SUM(G20:DG20) -> 3
B21: ВЭУ-42 | C21: 1 | D21: 1 | E21: 1 | F21: 1 | BF21: 1 | BG21: 1 | BH21: 1 | DH21: =SUM(G21:DG21) -> 3
B22: ВЭУ-47 | C22: 1 | D22: 1 | E22: 1 | F22: 1 | BI22: 1 | BJ22: 1 | BK22: 1 | DH22: =SUM(G22:DG22) -> 3
B23: ВЭУ-48 | C23: 1 | D23: 1 | E23: 1 | F23: 1 | BI23: 1 | BJ23: 1 | BK23: 1 | DH23: =SUM(G23:DG23) -> 3
B24: ВЭУ-51 | C24: 1 | D24: 1 | E24: 1 | F24: 1 | BL24: 1 | BM24: 1 | BN24: 1 | DH24: =SUM(G24:DG24) -> 3
B25: ИТОГО | C25: =SUM(C9:C24) -> 16 | D25: =SUM(D9:D24) -> 16 | E25: =SUM(E9:E24) -> 16 | F25: =SUM(F9:F24) -> 16 | G25: =SUM(G9:G24) -> 2 | H25: =SUM(H9:H24) -> 2 | I25: =SUM(I9:I24) -> 2 | J25: =SUM(J9:J24) -> 2 | ... DH25: =SUM(DH9:DH24) -> 48
B26: АНКЕРНЫЕ БНС | D26: ПЛАН | G26: ДАТА ПОСТАВКИ | DH26: ИТОГО
G27: 46174 | CS27: 46204
D28: Кол-во каркасов | G28: 01 | J28: 02 | M28: 03 | P28: 04 | S28: 05 | V28: 06 | Y28: 07 | AB28: 08 | AE28: 09 | AH28: 10 | AK28: 11 | AN28: 12 | AQ28: 13 | AT28: 14 | AW28: 15 | AZ28: 16 | BC28: 17 | BF28: 18 | BI28: 19 | BL28: 20 | BO28: 21 | BR28: 22 | BU28: 23 | BX28: 24 | CA28: 25 | CD28: 26 | CG28: 27 | CJ28: 28 | CM28: 29 | CP28: 30 | CS28: 01 | CV28: 02 | CY28: 03 | DB28: 04 | DE28: 05
B29: №ВЭУ | C29: кол-во свай | D29: КП-1 | E29: КП-2 | F29: КП-3 | G29: КП-1 | H29: КП-2 | I29: КП-3 | J29: КП-1 | K29: КП-2 | L29: КП-3 | M29: КП-1 | N29: КП-2 | O29: КП-3 | P29: КП-1 | Q29: КП-2 | R29: КП-3 | S29: КП-1 | T29: КП-2 | U29: КП-3 | V29: КП-1 | W29: КП-2 | X29: КП-3 | Y29: КП-1 | Z29: КП-2 | AA29: КП-3 | AB29: КП-1 | AC29: КП-2 | AD29: КП-3 | AE29: КП-1 | AF29: КП-2 | AG29: КП-3 | AH29: КП-1 | AI29: КП-2 | AJ29: КП-3 | AK29: КП-1 | AL29: КП-2 | AM29: КП-3 | AN29: КП-1 | AO29: КП-2 | AP29: КП-3 | AQ29: КП-1 | AR29: КП-2 | AS29: КП-3 | AT29: КП-1 | AU29: КП-2 | AV29: КП-3 | AW29: КП-1 | AX29: КП-2 | AY29: КП-3 | AZ29: КП-1 | BA29: КП-2 | BB29: КП-3 | BC29: КП-1 | BD29: КП-2 | BE29: КП-3 | BF29: КП-1 | BG29: КП-2 | BH29: КП-3 | BI29: КП-1 | BJ29: КП-2 | BK29: КП-3 | BL29: КП-1 | BM29: КП-2 | BN29: КП-3 | BO29: КП-1 | BP29: КП-2 | BQ29: КП-3 | BR29: КП-1 | BS29: КП-2 | BT29: КП-3 | BU29: КП-1 | BV29: КП-2 | BW29: КП-3 | BX29: КП-1 | BY29: КП-2 | BZ29: КП-3 | CA29: КП-1 | CB29: КП-2 | CC29: КП-3 | CD29: КП-1 | CE29: КП-2 | CF29: КП-3 | CG29: КП-1 | CH29: КП-2 | CI29: КП-3 | CJ29: КП-1 | CK29: КП-2 | CL29: КП-3 | CM29: КП-1 | CN29: КП-2 | CO29: КП-3 | CP29: КП-1 | CQ29: КП-2 | CR29: КП-3 | CS29: КП-1 | CT29: КП-2 | CU29: КП-3 | CV29: КП-1 | CW29: КП-2 | CX29: КП-3 | CY29: КП-1 | CZ29: КП-2 | DA29: КП-3 | DB29: КП-1 | DC29: КП-2 | DD29: КП-3 | DE29: КП-1 | DF29: КП-2 | DG29: КП-3
B30: ВЭУ-2 | C30: 2 | D30: 2 | E30: 2 | F30: 2 | G30: 2 | H30: 2 | I30: 2 | DH30: =SUM(G30:DG30) -> 6
B31: ВЭУ-6 | C31: 2 | D31: 2 | E31: 2 | F31: 2 | G31: 2 | H31: 2 | I31: 2 | DH31: =SUM(G31:DG31) -> 6
B32: ВЭУ-10 | C32: 2 | D32: 2 | E32: 2 | F32: 2 | J32: 2 | K32: 2 | L32: 2 | DH32: =SUM(G32:DG32) -> 6
B33: ВЭУ-15 | C33: 2 | D33: 2 | E33: 2 | F33: 2 | J33: 2 | K33: 2 | L33: 2 | DH33: =SUM(G33:DG33) -> 6
B34: ВЭУ-18 | C34: 2 | D34: 2 | E34: 2 | F34: 2 | M34: 2 | N34: 2 | O34: 2 | DH34: =SUM(G34:DG34) -> 6
B35: ВЭУ-19 | C35: 2 | D35: 2 | E35: 2 | F35: 2 | M35: 2 | N35: 2 | O35: 2 | DH35: =SUM(G35:DG35) -> 6
B36: ВЭУ-20 | C36: 2 | D36: 2 | E36: 2 | F36: 2 | P36: 2 | Q36: 2 | R36: 2 | DH36: =SUM(G36:DG36) -> 6
B37: ВЭУ-22 | C37: 2 | D37: 2 | E37: 2 | F37: 2 | AZ37: 2 | BA37: 2 | BB37: 2 | DH37: =SUM(G37:DG37) -> 6
B38: ВЭУ-25 | C38: 2 | D38: 2 | E38: 2 | F38: 2 | AZ38: 2 | BA38: 2 | BB38: 2 | DH38: =SUM(G38:DG38) -> 6
B39: ВЭУ-31 | C39: 2 | D39: 2 | E39: 2 | F39: 2 | BC39: 2 | BD39: 2 | BE39: 2 | DH39: =SUM(G39:DG39) -> 6
B40: ВЭУ-37 | C40: 2 | D40: 2 | E40: 2 | F40: 2 | BC40: 2 | BD40: 2 | BE40: 2 | DH40: =SUM(G40:DG40) -> 6
B41: ВЭУ-38 | C41: 2 | D41: 2 | E41: 2 | F41: 2 | BF41: 2 | BG41: 2 | BH41: 2 | DH41: =SUM(G41:DG41) -> 6
B42: ВЭУ-42 | C42: 2 | D42: 2 | E42: 2 | F42: 2 | BF42: 2 | BG42: 2 | BH42: 2 | DH42: =SUM(G42:DG42) -> 6
...

Sheet ИД Основные сваи
A1: №ВЭУ | C1: № сваи | D1: Дата заливки | E1: АОСР | F1: Статус ИД (АОСР) | G1: Статус - Залито/Не залито
A2: ВЭУ-1 | B2: ВЭУ-1 | C2: 1 | D2: =IF('1'!E5="","",'1'!E5) | E2: Комплект | G2: =IF(OR(D2="", D2=0, ISBLANK(D2)), "Не залито", "Залито") -> Не залито
A3: ВЭУ-1 | C3: 2 | D3: =IF('1'!E6="","",'1'!E6) | E3: Комплект | G3: =IF(OR(D3="", D3=0, ISBLANK(D3)), "Не залито", "Залито") -> Не залито
A4: ВЭУ-1 | C4: 3 | D4: =IF('1'!E7="","",'1'!E7) | E4: Комплект | G4: =IF(OR(D4="", D4=0, ISBLANK(D4)), "Не залито", "Залито") -> Не залито
A5: ВЭУ-1 | C5: 4 | D5: =IF('1'!E8="","",'1'!E8) | E5: Комплект | G5: =IF(OR(D5="", D5=0, ISBLANK(D5)), "Не залито", "Залито") -> Не залито
A6: ВЭУ-1 | C6: 5 | D6: =IF('1'!E9="","",'1'!E9) | E6: Комплект | G6: =IF(OR(D6="", D6=0, ISBLANK(D6)), "Не залито", "Залито") -> Не залито
A7: ВЭУ-1 | C7: 6 | D7: =IF('1'!E10="","",'1'!E10) | E7: Комплект | G7: =IF(OR(D7="", D7=0, ISBLANK(D7)), "Не залито", "Залито") -> Не залито
A8: ВЭУ-1 | C8: 7 | D8: =IF('1'!E11="","",'1'!E11) | E8: Комплект | G8: =IF(OR(D8="", D8=0, ISBLANK(D8)), "Не залито", "Залито") -> Не залито
A9: ВЭУ-1 | C9: 8 | D9: =IF('1'!E12="","",'1'!E12) | E9: Комплект | G9: =IF(OR(D9="", D9=0, ISBLANK(D9)), "Не залито", "Залито") -> Не залито
A10: ВЭУ-1 | C10: 9 | D10: =IF('1'!E13="","",'1'!E13) | E10: Комплект | G10: =IF(OR(D10="", D10=0, ISBLANK(D10)), "Не залито", "Залито") -> Не залито
A11: ВЭУ-1 | C11: 10 | D11: =IF('1'!E14="","",'1'!E14) | E11: Комплект | G11: =IF(OR(D11="", D11=0, ISBLANK(D11)), "Не залито", "Залито") -> Не залито
A12: ВЭУ-1 | C12: 11 | D12: =IF('1'!E15="","",'1'!E15) | E12: Комплект | G12: =IF(OR(D12="", D12=0, ISBLANK(D12)), "Не залито", "Залито") -> Не залито
A13: ВЭУ-1 | C13: 12 | D13: =IF('1'!E16="","",'1'!E16) | E13: Комплект | G13: =IF(OR(D13="", D13=0, ISBLANK(D13)), "Не залито", "Залито") -> Не залито
A14: ВЭУ-1 | C14: 13 | D14: =IF('1'!E17="","",'1'!E17) | E14: Комплект | G14: =IF(OR(D14="", D14=0, ISBLANK(D14)), "Не залито", "Залито") -> Не залито
... A25: ВЭУ-1 | C25: 24 | D25: =IF('1'!E28="","",'1'!E28) | E25: Комплект | G25: =IF(OR(D25="", D25=0, ISBLANK(D25)), "Не залито", "Залито") -> Не залито
A26: ВЭУ-2 | B26: ВЭУ-2 | C26: 1 | D26: =IF('2'!E5="","",'2'!E5) | E26: Комплект | G26: =IF(OR(D26="", D26=0, ISBLANK(D26)), "Не залито", "Залито") -> Не залито
A27: ВЭУ-2 | C27: 2 | D27: =IF('2'!E6="","",'2'!E6) -> 46253 | E27: Комплект | G27: =IF(OR(D27="", D27=0, ISBLANK(D27)), "Не залито", "Залито") -> Залито
A28: ВЭУ-2 | C28: 3 | D28: =IF('2'!E7="","",'2'!E7) -> 46252 | E28: Комплект | G28: =IF(OR(D28="", D28=0, ISBLANK(D28)), "Не залито", "Залито") -> Залито
A29: ВЭУ-2 | C29: 4 | D29: =IF('2'!E8="","",'2'!E8) -> 46248 | E29: Комплект | G29: =IF(OR(D29="", D29=0, ISBLANK(D29)), "Не залито", "Залито") -> Залито
A30: ВЭУ-2 | C30: 5 | D30: =IF('2'!E9="","",'2'!E9) -> 46251 | E30: Комплект | G30: =IF(OR(D30="", D30=0, ISBLANK(D30)), "Не залито", "Залито") -> Залито
A31: ВЭУ-2 | C31: 6 | D31: =IF('2'!E10="","",'2'!E10) -> 46247 | E31: Комплект | G31: =IF(OR(D31="", D31=0, ISBLANK(D31)), "Не залито", "Залито") -> Залито
A32: ВЭУ-2 | C32: 7 | D32: =IF('2'!E11="","",'2'!E11) -> 46250 | E32: Комплект | G32: =IF(OR(D32="", D32=0, ISBLANK(D32)), "Не залито", "Залито") -> Залито
A33: ВЭУ-2 | C33: 8 | D33: =IF('2'!E12="","",'2'!E12) -> 46247 | E33: Комплект | G33: =IF(OR(D33="", D33=0, ISBLANK(D33)), "Не залито", "Залито") -> Залито
A34: ВЭУ-2 | C34: 9 | D34: =IF('2'!E13="","",'2'!E13) -> 46250 | E34: Комплект | G34: =IF(OR(D34="", D34=0, ISBLANK(D34)), "Не залито", "Залито") -> Залито
A35: ВЭУ-2 | C35: 10 | D35: =IF('2'!E14="","",'2'!E14) -> 46246 | E35: Комплект | G35: =IF(OR(D35="", D35=0, ISBLANK(D35)), "Не залито", "Залито") -> Залито
A36: ВЭУ-2 | C36: 11 | D36: =IF('2'!E15="","",'2'!E15) -> 46250 | E36: Комплект | G36: =IF(OR(D36="", D36=0, ISBLANK(D36)), "Не залито", "Залито") -> Залито
A37: ВЭУ-2 | C37: 12 | D37: =IF('2'!E16="","",'2'!E16) -> 46246 | E37: Комплект | G37: =IF(OR(D37="", D37=0, ISBLANK(D37)), "Не залито", "Залито") -> Залито
A38: ВЭУ-2 | C38: 13 | D38: =IF('2'!E17="","",'2'!E17) -> 46250 | E38: Комплект | G38: =IF(OR(D38="", D38=0, ISBLANK(D38)), "Не залито", "Залито") -> Залито
... A49: ВЭУ-2 | C49: 24 | D49: =IF('2'!E28="","",'2'!E28) -> 46253 | E49: Комплект | G49: =IF(OR(D49="", D49=0, ISBLANK(D49)), "Не залито", "Залито") -> Залито
A50: ВЭУ-3 | B50: ВЭУ-3 | C50: 1 | D50: =IF('3'!E5="","",'3'!E5) -> 46248 | E50: Комплект | G50: =IF(OR(D50="", D50=0, ISBLANK(D50)), "Не залито", "Залито") -> Залито
A51: ВЭУ-3 | C51: 2 | D51: =IF('3'!E6="","",'3'!E6) -> 46250 | E51: Комплект | G51: =IF(OR(D51="", D51=0, ISBLANK(D51)), "Не залито", "Залито") -> Залито
A52: ВЭУ-3 | C52: 3 | D52: =IF('3'!E7="","",'3'!E7) -> 46246 | E52: Комплект | G52: =IF(OR(D52="", D52=0, ISBLANK(D52)), "Не залито", "Залито") -> Залито
A53: ВЭУ-3 | C53: 4 | D53: =IF('3'!E8="","",'3'!E8) -> 46239 | E53: Комплект | G53: =IF(OR(D53="", D53=0, ISBLANK(D53)), "Не залито", "Залито") -> Залито
A54: ВЭУ-3 | C54: 5 | D54: =IF('3'!E9="","",'3'!E9) -> 46247 | E54: Комплект | G54: =IF(OR(D54="", D54=0, ISBLANK(D54)), "Не залито", "Залито") -> Залито
A55: ВЭУ-3 | C55: 6 | D55: =IF('3'!E10="","",'3'!E10) -> 46249 | E55: Комплект | G55: =IF(OR(D55="", D55=0, ISBLANK(D55)), "Не залито", "Залито") -> Залито
A56: ВЭУ-3 | C56: 7 | D56: =IF('3'!E11="","",'3'!E11) -> 46244 | E56: Комплект | G56: =IF(OR(D56="", D56=0, ISBLANK(D56)), "Не залито", "Залито") -> Залито
A57: ВЭУ-3 | C57: 8 | D57: =IF('3'!E12="","",'3'!E12) -> 46248 | E57: Комплект | G57: =IF(OR(D57="", D57=0, ISBLANK(D57)), "Не залито", "Залито") -> Залито
A58: ВЭУ-3 | C58: 9 | D58: =IF('3'!E13="","",'3'!E13) -> 46241 | E58: Комплект | G58: =IF(OR(D58="", D58=0, ISBLANK(D58)), "Не залито", "Залито") -> Залито
A59: ВЭУ-3 | C59: 10 | D59: =IF('3'!E14="","",'3'!E14) -> 46237 | E59: Комплект | G59: =IF(OR(D59="", D59=0, ISBLANK(D59)), "Не залито", "Залито") -> Залито
A60: ВЭУ-3 | C60: 11 | D60: =IF('3'!E15="","",'3'!E15) -> 46240 | E60: Комплект | G60: =IF(OR(D60="", D60=0, ISBLANK(D60)), "Не залито", "Залито") -> Залито
...

Sheet Геология
A1: №ВЭУ | C1: № сваи | D1: Дата заливки | E1: Фото геологии | F1: Статус ИД
A2: ВЭУ-1 | B2: ВЭУ-1 | C2: 1 | D2: =IF('1'!E5="","",'1'!E5)
A3: ВЭУ-1 | C3: 2 | D3: =IF('1'!E6="","",'1'!E6)
A4: ВЭУ-1 | C4: 3 | D4: =IF('1'!E7="","",'1'!E7)
A5: ВЭУ-1 | C5: 4 | D5: =IF('1'!E8="","",'1'!E8)
A6: ВЭУ-1 | C6: 5 | D6: =IF('1'!E9="","",'1'!E9)
A7: ВЭУ-1 | C7: 6 | D7: =IF('1'!E10="","",'1'!E10)
A8: ВЭУ-1 | C8: 7 | D8: =IF('1'!E11="","",'1'!E11)
A9: ВЭУ-1 | C9: 8 | D9: =IF('1'!E12="","",'1'!E12)
A10: ВЭУ-1 | C10: 9 | D10: =IF('1'!E13="","",'1'!E13)
A11: ВЭУ-1 | C11: 10 | D11: =IF('1'!E14="","",'1'!E14)
A12: ВЭУ-1 | C12: 11 | D12: =IF('1'!E15="","",'1'!E15)
A13: ВЭУ-1 | C13: 12 | D13: =IF('1'!E16="","",'1'!E16)
A14: ВЭУ-1 | C14: 13 | D14: =IF('1'!E17="","",'1'!E17)
... A25: ВЭУ-1 | C25: 24 | D25: =IF('1'!E28="","",'1'!E28)
A26: ВЭУ-2 | B26: ВЭУ-2 | C26: 1 | D26: =IF('2'!E5="","",'2'!E5)
A27: ВЭУ-2 | C27: 2 | D27: =IF('2'!E6="","",'2'!E6) -> 46253
A28: ВЭУ-2 | C28: 3 | D28: =IF('2'!E7="","",'2'!E7) -> 46252
A29: ВЭУ-2 | C29: 4 | D29: =IF('2'!E8="","",'2'!E8) -> 46248
A30: ВЭУ-2 | C30: 5 | D30: =IF('2'!E9="","",'2'!E9) -> 46251
A31: ВЭУ-2 | C31: 6 | D31: =IF('2'!E10="","",'2'!E10) -> 46247
A32: ВЭУ-2 | C32: 7 | D32: =IF('2'!E11="","",'2'!E11) -> 46250
A33: ВЭУ-2 | C33: 8 | D33: =IF('2'!E12="","",'2'!E12) -> 46247
A34: ВЭУ-2 | C34: 9 | D34: =IF('2'!E13="","",'2'!E13) -> 46250
A35: ВЭУ-2 | C35: 10 | D35: =IF('2'!E14="","",'2'!E14) -> 46246
A36: ВЭУ-2 | C36: 11 | D36: =IF('2'!E15="","",'2'!E15) -> 46250
A37: ВЭУ-2 | C37: 12 | D37: =IF('2'!E16="","",'2'!E16) -> 46246
A38: ВЭУ-2 | C38: 13 | D38: =IF('2'!E17="","",'2'!E17) -> 46250
... A49: ВЭУ-2 | C49: 24 | D49: =IF('2'!E28="","",'2'!E28) -> 46253
A50: ВЭУ-3 | B50: ВЭУ-3 | C50: 1 | D50: =IF('3'!E5="","",'3'!E5) -> 46248
A51: ВЭУ-3 | C51: 2 | D51: =IF('3'!E6="","",'3'!E6) -> 46250
A52: ВЭУ-3 | C52: 3 | D52: =IF('3'!E7="","",'3'!E7) -> 46246
A53: ВЭУ-3 | C53: 4 | D53: =IF('3'!E8="","",'3'!E8) -> 46239 | E53: +
A54: ВЭУ-3 | C54: 5 | D54: =IF('3'!E9="","",'3'!E9) -> 46247
A55: ВЭУ-3 | C55: 6 | D55: =IF('3'!E10="","",'3'!E10) -> 46249
A56: ВЭУ-3 | C56: 7 | D56: =IF('3'!E11="","",'3'!E11) -> 46244
A57: ВЭУ-3 | C57: 8 | D57: =IF('3'!E12="","",'3'!E12) -> 46248
A58: ВЭУ-3 | C58: 9 | D58: =IF('3'!E13="","",'3'!E13) -> 46241
A59: ВЭУ-3 | C59: 10 | D59: =IF('3'!E14="","",'3'!E14) -> 46237 | E59: +
A60: ВЭУ-3 | C60: 11 | D60: =IF('3'!E15="","",'3'!E15) -> 46240
...

Sheet Промежуточный акт (Бегунок)
A1: №ВЭУ | C1: № сваи | D1: Дата заливки | E1: Промежуточный акт (Бегунок)
A2: ВЭУ-1 | B2: ВЭУ-1 | C2: 1 | D2: =IF('1'!E5="","",'1'!E5)
A3: ВЭУ-1 | C3: 2 | D3: =IF('1'!E6="","",'1'!E6)
A4: ВЭУ-1 | C4: 3 | D4: =IF('1'!E7="","",'1'!E7)
A5: ВЭУ-1 | C5: 4 | D5: =IF('1'!E8="","",'1'!E8)
A6: ВЭУ-1 | C6: 5 | D6: =IF('1'!E9="","",'1'!E9)
A7: ВЭУ-1 | C7: 6 | D7: =IF('1'!E10="","",'1'!E10)
A8: ВЭУ-1 | C8: 7 | D8: =IF('1'!E11="","",'1'!E11)
A9: ВЭУ-1 | C9: 8 | D9: =IF('1'!E12="","",'1'!E12)
A10: ВЭУ-1 | C10: 9 | D10: =IF('1'!E13="","",'1'!E13)
A11: ВЭУ-1 | C11: 10 | D11: =IF('1'!E14="","",'1'!E14)
A12: ВЭУ-1 | C12: 11 | D12: =IF('1'!E15="","",'1'!E15)
A13: ВЭУ-1 | C13: 12 | D13: =IF('1'!E16="","",'1'!E16)
A14: ВЭУ-1 | C14: 13 | D14: =IF('1'!E17="","",'1'!E17)
... A25: ВЭУ-1 | C25: 24 | D25: =IF('1'!E28="","",'1'!E28)
A26: ВЭУ-2 | B26: ВЭУ-2 | C26: 1 | D26: =IF('2'!E5="","",'2'!E5)
A27: ВЭУ-2 | C27: 2 | D27: =IF('2'!E6="","",'2'!E6) -> 46253
A28: ВЭУ-2 | C28: 3 | D28: =IF('2'!E7="","",'2'!E7) -> 46252
A29: ВЭУ-2 | C29: 4 | D29: =IF('2'!E8="","",'2'!E8) -> 46248
A30: ВЭУ-2 | C30: 5 | D30: =IF('2'!E9="","",'2'!E9) -> 46251
A31: ВЭУ-2 | C31: 6 | D31: =IF('2'!E10="","",'2'!E10) -> 46247
A32: ВЭУ-2 | C32: 7 | D32: =IF('2'!E11="","",'2'!E11) -> 46250
A33: ВЭУ-2 | C33: 8 | D33: =IF('2'!E12="","",'2'!E12) -> 46247
A34: ВЭУ-2 | C34: 9 | D34: =IF('2'!E13="","",'2'!E13) -> 46250
A35: ВЭУ-2 | C35: 10 | D35: =IF('2'!E14="","",'2'!E14) -> 46246
A36: ВЭУ-2 | C36: 11 | D36: =IF('2'!E15="","",'2'!E15) -> 46250
A37: ВЭУ-2 | C37: 12 | D37: =IF('2'!E16="","",'2'!E16) -> 46246
A38: ВЭУ-2 | C38: 13 | D38: =IF('2'!E17="","",'2'!E17) -> 46250
... A49: ВЭУ-2 | C49: 24 | D49: =IF('2'!E28="","",'2'!E28) -> 46253
A50: ВЭУ-3 | B50: ВЭУ-3 | C50: 1 | D50: =IF('3'!E5="","",'3'!E5) -> 46248
A51: ВЭУ-3 | C51: 2 | D51: =IF('3'!E6="","",'3'!E6) -> 46250
A52: ВЭУ-3 | C52: 3 | D52: =IF('3'!E7="","",'3'!E7) -> 46246
A53: ВЭУ-3 | C53: 4 | D53: =IF('3'!E8="","",'3'!E8) -> 46239
A54: ВЭУ-3 | C54: 5 | D54: =IF('3'!E9="","",'3'!E9) -> 46247
A55: ВЭУ-3 | C55: 6 | D55: =IF('3'!E10="","",'3'!E10) -> 46249
A56: ВЭУ-3 | C56: 7 | D56: =IF('3'!E11="","",'3'!E11) -> 46244
A57: ВЭУ-3 | C57: 8 | D57: =IF('3'!E12="","",'3'!E12) -> 46248
A58: ВЭУ-3 | C58: 9 | D58: =IF('3'!E13="","",'3'!E13) -> 46241
A59: ВЭУ-3 | C59: 10 | D59: =IF('3'!E14="","",'3'!E14) -> 46237
A60: ВЭУ-3 | C60: 11 | D60: =IF('3'!E15="","",'3'!E15) -> 46240
...

Sheet 1
A1: ОСНОВНЫЕ БНС | C1: м3 (проект) | E1: Дата заливки | F1: ДКБС№ | G1: м3 (ДКБС) | H1: ДКБС№ | I1: м3 (ДКБС) | J1: ДКБС№ | K1: м3 (ДКБС) | L1: ДКБС№ | M1: м3 (ДКБС) | N1: Итого | O1: Разница (Проект-Факт) | P1: 7 суток (Протокол) | Q1: 14 суток (Протокол) | R1: 28 суток (Протокол) | S1: 7 суток (Протокол) Статус | T1: 14 суток (Статус) | U1: 28 суток (Протокол) Статус
A4: №ВЭУ | B4: № сваи
A5: ВЭУ-1 | B5: 1 | C5: 26.27 | N5: =G5+I5+K5+M5 -> 0 | O5: =N5-C5 -> -26.27 | P5: =E5+7 -> 7 | Q5: =E5+14 -> 14 | R5: =E5+28 -> 28
B6: 2 | C6: 26.27 | N6: =G6+I6+K6+M6 -> 0 | O6: =N6-C6 -> -26.27 | P6: =E6+7 -> 7 | Q6: =E6+14 -> 14 | R6: =E6+28 -> 28
B7: 3 | C7: 26.27 | N7: =G7+I7+K7+M7 -> 0 | O7: =N7-C7 -> -26.27 | P7: =E7+7 -> 7 | Q7: =E7+14 -> 14 | R7: =E7+28 -> 28 | U7: -
B8: 4 | C8: 26.27 | N8: =G8+I8+K8+M8 -> 0 | O8: =N8-C8 -> -26.27 | P8: =E8+7 -> 7 | Q8: =E8+14 -> 14 | R8: =E8+28 -> 28
B9: 5 | C9: 26.27 | N9: =G9+I9+K9+M9 -> 0 | O9: =N9-C9 -> -26.27 | P9: =E9+7 -> 7 | Q9: =E9+14 -> 14 | R9: =E9+28 -> 28
B10: 6 | C10: 26.27 | N10: =G10+I10+K10+M10 -> 0 | O10: =N10-C10 -> -26.27 | P10: =E10+7 -> 7 | Q10: =E10+14 -> 14 | R10: =E10+28 -> 28
B11: 7 | C11: 26.27 | N11: =G11+I11+K11+M11 -> 0 | O11: =N11-C11 -> -26.27 | P11: =E11+7 -> 7 | Q11: =E11+14 -> 14 | R11: =E11+28 -> 28
B12: 8 | C12: 26.27 | N12: =G12+I12+K12+M12 -> 0 | O12: =N12-C12 -> -26.27 | P12: =E12+7 -> 7 | Q12: =E12+14 -> 14 | R12: =E12+28 -> 28
B13: 9 | C13: 26.27 | N13: =G13+I13+K13+M13 -> 0 | O13: =N13-C13 -> -26.27 | P13: =E13+7 -> 7 | Q13: =E13+14 -> 14 | R13: =E13+28 -> 28
B14: 10 | C14: 26.27 | N14: =G14+I14+K14+M14 -> 0 | O14: =N14-C14 -> -26.27 | P14: =E14+7 -> 7 | Q14: =E14+14 -> 14 | R14: =E14+28 -> 28
B15: 11 | C15: 26.27 | N15: =G15+I15+K15+M15 -> 0 | O15: =N15-C15 -> -26.27 | P15: =E15+7 -> 7 | Q15: =E15+14 -> 14 | R15: =E15+28 -> 28
B16: 12 | C16: 26.27 | N16: =G16+I16+K16+M16 -> 0 | O16: =N16-C16 -> -26.27 | P16: =E16+7 -> 7 | Q16: =E16+14 -> 14 | R16: =E16+28 -> 28
B17: 13 | C17: 26.27 | N17: =G17+I17+K17+M17 -> 0 | O17: =N17-C17 -> -26.27 | P17: =E17+7 -> 7 | Q17: =E17+14 -> 14 | R17: =E17+28 -> 28
B18: 14 | C18: 26.27 | N18: =G18+I18+K18+M18 -> 0 | O18: =N18-C18 -> -26.27 | P18: =E18+7 -> 7 | Q18: =E18+14 -> 14 | R18: =E18+28 -> 28
B19: 15 | C19: 26.27 | N19: =G19+I19+K19+M19 -> 0 | O19: =N19-C19 -> -26.27 | P19: =E19+7 -> 7 | Q19: =E19+14 -> 14 | R19: =E19+28 -> 28
... B28: 24 | C28: 26.27 | N28: =G28+I28+K28+M28 -> 0 | O28: =N28-C28 -> -26.27 | P28: =E28+7 -> 7 | Q28: =E28+14 -> 14 | R28: =E28+28 -> 28
A29: Итого | C29: =SUM(C5:D28) -> 630.48

Sheet 2
A1: ОСНОВНЫЕ БНС | C1: м3 (проект) | E1: Дата заливки | F1: ДКБС№ | G1: м3 (ДКБС) | H1: ДКБС№ | I1: м3 (ДКБС) | J1: ДКБС№ | K1: м3 (ДКБС) | L1: ДКБС№ | M1: м3 (ДКБС) | N1: Итого | O1: Разница (Проект-Факт) | P1: 7 суток (Протокол) | Q1: 14 суток (Протокол) | R1: 28 суток (Протокол) | S1: 7 суток (Протокол) Статус | T1: 14 суток (Статус) | U1: 28 суток (Протокол) Статус
A4: №ВЭУ | B4: № сваи
A5: ВЭУ-2 | B5: 1 | C5: 27.4 | N5: =G5+I5+K5+M5 -> 0 | O5: =N5-C5 -> -27.4 | P5: =E5+7 -> 7 | Q5: =E5+14 -> 14 | R5: =E5+28 -> 28
B6: 2 | C6: 27.4 | E6: 46253 | N6: =G6+I6+K6+M6 -> 0 | O6: =N6-C6 -> -27.4 | P6: =E6+7 -> 46260 | Q6: =E6+14 -> 46267 | R6: =E6+28 -> 46281
B7: 3 | C7: 27.4 | E7: 46252 | N7: =G7+I7+K7+M7 -> 0 | O7: =N7-C7 -> -27.4 | P7: =E7+7 -> 46259 | Q7: =E7+14 -> 46266 | R7: =E7+28 -> 46280 | U7: -
B8: 4 | C8: 27.4 | E8: 46248 | N8: =G8+I8+K8+M8 -> 0 | O8: =N8-C8 -> -27.4 | P8: =E8+7 -> 46255 | Q8: =E8+14 -> 46262 | R8: =E8+28 -> 46276
B9: 5 | C9: 27.4 | E9: 46251 | N9: =G9+I9+K9+M9 -> 0 | O9: =N9-C9 -> -27.4 | P9: =E9+7 -> 46258 | Q9: =E9+14 -> 46265 | R9: =E9+28 -> 46279
B10: 6 | C10: 27.4 | E10: 46247 | F10: 59/16 | G10: 9 | H10: 59/17 | I10: 9 | J10: 59/18 | K10: 9 | N10: =G10+I10+K10+M10 -> 27 | O10: =N10-C10 -> -0.4 | P10: =E10+7 -> 46254 | Q10: =E10+14 -> 46261 | R10: =E10+28 -> 46275
B11: 7 | C11: 27.4 | E11: 46250 | N11: =G11+I11+K11+M11 -> 0 | O11: =N11-C11 -> -27.4 | P11: =E11+7 -> 46257 | Q11: =E11+14 -> 46264 | R11: =E11+28 -> 46278
B12: 8 | C12: 27.4 | E12: 46247 | F12: 59/10 | G12: 9 | H12: 59/11 | I12: 9 | J12: 59/12 | K12: 9 | N12: =G12+I12+K12+M12 -> 27 | O12: =N12-C12 -> -0.4 | P12: =E12+7 -> 46254 | Q12: =E12+14 -> 46261 | R12: =E12+28 -> 46275
B13: 9 | C13: 27.4 | E13: 46250 | N13: =G13+I13+K13+M13 -> 0 | O13: =N13-C13 -> -27.4 | P13: =E13+7 -> 46257 | Q13: =E13+14 -> 46264 | R13: =E13+28 -> 46278
B14: 10 | C14: 27.4 | E14: 46246 | F14: 58/33 | G14: 9 | H14: 58/32 | I14: 9.5 | J14: 58/31 | K14: 9.5 | N14: =G14+I14+K14+M14 -> 28 | O14: =N14-C14 -> 0.6 | P14: =E14+7 -> 46253 | Q14: =E14+14 -> 46260 | R14: =E14+28 -> 46274
B15: 11 | C15: 27.4 | E15: 46250 | N15: =G15+I15+K15+M15 -> 0 | O15: =N15-C15 -> -27.4 | P15: =E15+7 -> 46257 | Q15: =E15+14 -> 46264 | R15: =E15+28 -> 46278
B16: 12 | C16: 27.4 | E16: 46246 | F16: 58/12 | G16: 9 | H16: 58/11 | I16: 9.5 | J16: 58/10 | K16: 9.5 | N16: =G16+I16+K16+M16 -> 28 | O16: =N16-C16 -> 0.6 | P16: =E16+7 -> 46253 | Q16: =E16+14 -> 46260 | R16: =E16+28 -> 46274
B17: 13 | C17: 27.4 | E17: 46250 | N17: =G17+I17+K17+M17 -> 0 | O17: =N17-C17 -> -27.4 | P17: =E17+7 -> 46257 | Q17: =E17+14 -> 46264 | R17: =E17+28 -> 46278
B18: 14 | C18: 27.4 | E18: 46251 | N18: =G18+I18+K18+M18 -> 0 | O18: =N18-C18 -> -27.4 | P18: =E18+7 -> 46258 | Q18: =E18+14 -> 46265 | R18: =E18+28 -> 46279
B19: 15 | C19: 27.4 | E19: 46249 | N19: =G19+I19+K19+M19 -> 0 | O19: =N19-C19 -> -27.4 | P19: =E19+7 -> 46256 | Q19: =E19+14 -> 46263 | R19: =E19+28 -> 46277
B20: 16 | C20: 27.4 | E20: 46251 | N20: =G20+I20+K20+M20 -> 0 | O20: =N20-C20 -> -27.4 | P20: =E20+7 -> 46258 | Q20: =E20+14 -> 46265 | R20: =E20+28 -> 46279
B21: 17 | C21: 27.4 | E21: 46249 | N21: =G21+I21+K21+M21 -> 0 | O21: =N21-C21 -> -27.4 | P21: =E21+7 -> 46256 | Q21: =E21+14 -> 46263 | R21: =E21+28 -> 46277
B22: 18 | C22: 27.4 | E22: 46252 | N22: =G22+I22+K22+M22 -> 0 | O22: =N22-C22 -> -27.4 | P22: =E22+7 -> 46259 | Q22: =E22+14 -> 46266 | R22: =E22+28 -> 46280
B23: 19 | C23: 27.4 | E23: 46248 | N23: =G23+I23+K23+M23 -> 0 | O23: =N23-C23 -> -27.4 | P23: =E23+7 -> 46255 | Q23: =E23+14 -> 46262 | R23: =E23+28 -> 46276
B24: 20 | C24: 27.4 | E24: 46252 | N24: =G24+I24+K24+M24 -> 0 | O24: =N24-C24 -> -27.4 | P24: =E24+7 -> 46259 | Q24: =E24+14 -> 46266 | R24: =E24+28 -> 46280
B25: 21 | C25: 27.4 | E25: 46249 | N25: =G25+I25+K25+M25 -> 0 | O25: =N25-C25 -> -27.4 | P25: =E25+7 -> 46256 | Q25: =E25+14 -> 46263 | R25: =E25+28 -> 46277
B26: 22 | C26: 27.4 | E26: 46252 | N26: =G26+I26+K26+M26 -> 0 | O26: =N26-C26 -> -27.4 | P26: =E26+7 -> 46259 | Q26: =E26+14 -> 46266 | R26: =E26+28 -> 46280
B27: 23 | C27: 27.4 | N27: =G27+I27+K27+M27 -> 0 | O27: =N27-C27 -> -27.4 | P27: =E27+7 -> 7 | Q27: =E27+14 -> 14 | R27: =E27+28 -> 28
B28: 24 | C28: 27.4 | E28: 46253 | N28: =G28+I28+K28+M28 -> 0 | O28: =N28-C28 -> -27.4 | P28: =E28+7 -> 46260 | Q28: =E28+14 -> 46267 | R28: =E28+28 -> 46281
A29: Итого | C29: =SUM(C5:D28) -> 657.6

Sheet 3
A1: ОСНОВНЫЕ БНС | C1: м3 (проект) | E1: Дата заливки | F1: ДКБС№ | G1: м3 (ДКБС) | H1: ДКБС№ | I1: м3 (ДКБС) | J1: ДКБС№ | K1: м3 (ДКБС) | L1: ДКБС№ | M1: м3 (ДКБС) | N1: Итого | O1: Разница (Проект-Факт) | P1: 7 суток (Протокол) | Q1: 14 суток (Протокол) | R1: 28 суток (Протокол) | S1: 7 суток (Протокол) Статус | T1: 14 суток (Статус) | U1: 28 суток (Протокол) Статус
A4: №ВЭУ | B4: № сваи
A5: ВЭУ-3 | B5: 1 | C5: 27.4 | E5: 46248 | N5: =G5+I5+K5+M5 -> 0 | O5: =N5-C5 -> -27.4 | P5: =E5+7 -> 46255 | Q5: =E5+14 -> 46262 | R5: =E5+28 -> 46276
B6: 2 | C6: 27.4 | E6: 46250 | N6: =G6+I6+K6+M6 -> 0 | O6: =N6-C6 -> -27.4 | P6: =E6+7 -> 46257 | Q6: =E6+14 -> 46264 | R6: =E6+28 -> 46278
B7: 3 | C7: 27.4 | E7: 46246 | F7: 58/9 | G7: 9 | H7: 58/8 | I7: 9.5 | J7: 58/7 | K7: 9.5 | N7: =G7+I7+K7+M7 -> 28 | O7: =N7-C7 -> 0.6 | P7: =E7+7 -> 46253 | Q7: =E7+14 -> 46260 | R7: =E7+28 -> 46274 | U7: -
B8: 4 | C8: 27.4 | E8: 46239 | F8: 51/3 | G8: 9 | H8: 51/2 | I8: 9 | J8: 51/1 | K8: 9 | N8: =G8+I8+K8+M8 -> 27 | O8: =N8-C8 -> -0.4 | P8: =E8+7 -> 46246 | Q8: =E8+14 -> 46253 | R8: =E8+28 -> 46267 | S8: +
B9: 5 | C9: 27.4 | E9: 46247 | F9: 59/38 | G9: 9.5 | H9: 59/39 | I9: 9.5 | J9: 59/40 | K9: 9 | N9: =G9+I9+K9+M9 -> 28 | O9: =N9-C9 -> 0.6 | P9: =E9+7 -> 46254 | Q9: =E9+14 -> 46261 | R9: =E9+28 -> 46275
B10: 6 | C10: 27.4 | E10: 46249 | N10: =G10+I10+K10+M10 -> 0 | O10: =N10-C10 -> -27.4 | P10: =E10+7 -> 46256 | Q10: =E10+14 -> 46263 | R10: =E10+28 -> 46277
B11: 7 | C11: 27.4 | E11: 46244 | F11: 56/7 | G11: 9.5 | H11: 56/8 | I11: 9.5 | J11: 56/9 | K11: 9 | N11: =G11+I11+K11+M11 -> 28 | O11: =N11-C11 -> 0.6 | P11: =E11+7 -> 46251 | Q11: =E11+14 -> 46258 | R11: =E11+28 -> 46272
B12: 8 | C12: 27.4 | E12: 46248 | N12: =G12+I12+K12+M12 -> 0 | O12: =N12-C12 -> -27.4 | P12: =E12+7 -> 46255 | Q12: =E12+14 -> 46262 | R12: =E12+28 -> 46276
B13: 9 | C13: 27.4 | E13: 46241 | F13: 53/21 | G13: 9 | H13: 53/20 | I13: 9 | J13: 53/19 | K13: 9 | N13: =G13+I13+K13+M13 -> 27 | O13: =N13-C13 -> -0.4 | P13: =E13+7 -> 46248 | Q13: =E13+14 -> 46255 | R13: =E13+28 -> 46269 | S13: +
B14: 10 | C14: 27.4 | E14: 46237 | F14: №49/13 | G14: 9.5 | H14: №49/14 | I14: 9.5 | J14: №49/15 | K14: 9.5 | N14: =G14+I14+K14+M14 -> 28.5 | O14: =N14-C14 -> 1.1 | P14: =E14+7 -> 46244 | Q14: =E14+14 -> 46251 | R14: =E14+28 -> 46265 | S14: +
B15: 11 | C15: 27.4 | E15: 46240 | F15: 52/18 | G15: 9 | H15: 52/17 | I15: 9 | J15: 52/19 | K15: 9 | N15: =G15+I15+K15+M15 -> 27 | O15: =N15-C15 -> -0.4 | P15: =E15+7 -> 46247 | Q15: =E15+14 -> 46254 | R15: =E15+28 -> 46268 | S15: +
B16: 12 | C16: 27.4 | E16: 46238 | F16: 50/9 | G16: 9 | H16: 50/8 | I16: 9 | J16: 50/7 | K16: 9 | N16: =G16+I16+K16+M16 -> 27 | O16: =N16-C16 -> -0.4 | P16: =E16+7 -> 46245 | Q16: =E16+14 -> 46252 | R16: =E16+28 -> 46266 | S16: +
B17: 13 | C17: 27.4 | E17: 46239 | F17: 51/21 | G17: 9 | H17: 51/20 | I17: 9.5 | J17: 51/19 | K17: 9.5 | N17: =G17+I17+K17+M17 -> 28 | O17: =N17-C17 -> 0.6 | P17: =E17+7 -> 46246 | Q17: =E17+14 -> 46253 | R17: =E17+28 -> 46267 | S17: +
B18: 14 | C18: 27.4 | E18: 46241 | F18: 53/35 | G18: 9.5 | H18: 53/36 | I18: 9.5 | J18: 53/37 | K18: 9 | N18: =G18+I18+K18+M18 -> 28 | O18: =N18-C18 -> 0.6 | P18: =E18+7 -> 46248 | Q18: =E18+14 -> 46255 | R18: =E18+28 -> 46269 | S18: +
B19: 15 | C19: 27.4 | E19: 46240 | F19: 52/6 | G19: 9 | H19: 52/5 | I19: 9.5 | J19: 52/4 | K19: 9.5 | N19: =G19+I19+K19+M19 -> 28 | O19: =N19-C19 -> 0.6 | P19: =E19+7 -> 46247 | Q19: =E19+14 -> 46254 | R19: =E19+28 -> 46268 | S19: +
B20: 16 | C20: 27.4 | E20: 46238 | F20: 50/21 | G20: 9 | H20: 50/20 | I20: 9 | J20: 50/19 | K20: 9 | N20: =G20+I20+K20+M20 -> 27 | O20: =N20-C20 -> -0.4 | P20: =E20+7 -> 46245 | Q20: =E20+14 -> 46252 | R20: =E20+28 -> 46266 | S20: +
B21: 17 | C21: 27.4 | E21: 46244 | F21: 56/19 | G21: 9.5 | H21: 56/20 | I21: 9.5 | J21: 56/21 | K21: 9 | N21: =G21+I21+K21+M21 -> 28 | O21: =N21-C21 -> 0.6 | P21: =E21+7 -> 46251 | Q21: =E21+14 -> 46258 | R21: =E21+28 -> 46272
B22: 18 | C22: 27.4 | E22: 46246 | F22: 58/21 | G22: 9 | H22: 58/20 | I22: 9.5 | J22: 58/19 | K22: 9.5 | N22: =G22+I22+K22+M22 -> 28 | O22: =N22-C22 -> 0.6 | P22: =E22+7 -> 46253 | Q22: =E22+14 -> 46260 | R22: =E22+28 -> 46274
B23: 19 | C23: 27.4 | E23: 46243 | F23: 55/34 | G23: 10 | N23: =G23+I23+K23+M23 -> 10 | O23: =N23-C23 -> -17.4 | P23: =E23+7 -> 46250 | Q23: =E23+14 -> 46257 | R23: =E23+28 -> 46271
B24: 20 | C24: 27.4 | E24: 46247 | F24: 59/1 | G24: 9 | H24: 59/2 | I24: 9 | J24: 59/3 | K24: 9 | N24: =G24+I24+K24+M24 -> 27 | O24: =N24-C24 -> -0.4 | P24: =E24+7 -> 46254 | Q24: =E24+14 -> 46261 | R24: =E24+28 -> 46275
B25: 21 | C25: 27.4 | E25: 46242 | F25: 54/15 | G25: 9 | H25: 54/13 | I25: 9.5 | J25: 54/14 | K25: 9.5 | N25: =G25+I25+K25+M25 -> 28 | O25: =N25-C25 -> 0.6 | P25: =E25+7 -> 46249 | Q25: =E25+14 -> 46256 | R25: =E25+28 -> 46270
B26: 22 | C26: 27.4 | E26: 46241 | F26: 53/6 | G26: 9 | H26: 53/5 | I26: 9.5 | J26: 53/4 | K26: 9.5 | N26: =G26+I26+K26+M26 -> 28 | O26: =N26-C26 -> 0.6 | P26: =E26+7 -> 46248 | Q26: =E26+14 -> 46255 | R26: =E26+28 -> 46269 | S26: +
B27: 23 | C27: 27.4 | E27: 46245 | F27: 57/40 | G27: 9.5 | H27: 57/39 | I27: 9 | J27: 57/38 | K27: 9.5 | N27: =G27+I27+K27+M27 -> 28 | O27: =N27-C27 -> 0.6 | P27: =E27+7 -> 46252 | Q27: =E27+14 -> 46259 | R27: =E27+28 -> 46273
B28: 24 | C28: 27.4 | E28: 46250 | N28: =G28+I28+K28+M28 -> 0 | O28: =N28-C28 -> -27.4 | P28: =E28+7 -> 46257 | Q28: =E28+14 -> 46264 | R28: =E28+28 -> 46278
A29: Итого | C29: =SUM(C5:D28) -> 657.6

Sheet 4
A1: ОСНОВНЫЕ БНС | C1: м3 (проект) | E1: Дата заливки | F1: ДКБС№ | G1: м3 (ДКБС) | H1: ДКБС№ | I1: м3 (ДКБС) | J1: ДКБС№ | K1: м3 (ДКБС) | L1: ДКБС№ | M1: м3 (ДКБС) | N1: Итого | O1: Разница (Проект-Факт) | P1: 7 суток (Протокол) | Q1: 14 суток (Протокол) | R1: 28 суток (Протокол) | S1: 7 суток (Протокол) Статус | T1: 14 суток (Статус) | U1: 28 суток (Протокол) Статус
A4: №ВЭУ | B4: № сваи
A5: ВЭУ-4 | B5: 1 | C5: 27.4 | N5: =G5+I5+K5+M5 -> 0 | O5: =N5-C5 -> -27.4 | P5: =E5+7 -> 7 | Q5: =E5+14 -> 14 | R5: =E5+28 -> 28
B6: 2 | C6: 27.4 | N6: =G6+I6+K6+M6 -> 0 | O6: =N6-C6 -> -27.4 | P6: =E6+7 -> 7 | Q6: =E6+14 -> 14 | R6: =E6+28 -> 28
B7: 3 | C7: 27.4 | N7: =G7+I7+K7+M7 -> 0 | O7: =N7-C7 -> -27.4 | P7: =E7+7 -> 7 | Q7: =E7+14 -> 14 | R7: =E7+28 -> 28 | U7: -
B8: 4 | C8: 27.4 | N8: =G8+I8+K8+M8 -> 0 | O8: =N8-C8 -> -27.4 | P8: =E8+7 -> 7 | Q8: =E8+14 -> 14 | R8: =E8+28 -> 28
B9: 5 | C9: 27.4 | N9: =G9+I9+K9+M9 -> 0 | O9: =N9-C9 -> -27.4 | P9: =E9+7 -> 7 | Q9: =E9+14 -> 14 | R9: =E9+28 -> 28
B10: 6 | C10: 27.4 | N10: =G10+I10+K10+M10 -> 0 | O10: =N10-C10 -> -27.4 | P10: =E10+7 -> 7 | Q10: =E10+14 -> 14 | R10: =E10+28 -> 28
B11: 7 | C11: 27.4 | N11: =G11+I11+K11+M11 -> 0 | O11: =N11-C11 -> -27.4 | P11: =E11+7 -> 7 | Q11: =E11+14 -> 14 | R11: =E11+28 -> 28
B12: 8 | C12: 27.4 | N12: =G12+I12+K12+M12 -> 0 | O12: =N12-C12 -> -27.4 | P12: =E12+7 -> 7 | Q12: =E12+14 -> 14 | R12: =E12+28 -> 28
B13: 9 | C13: 27.4 | N13: =G13+I13+K13+M13 -> 0 | O13: =N13-C13 -> -27.4 | P13: =E13+7 -> 7 | Q13: =E13+14 -> 14 | R13: =E13+28 -> 28
B14: 10 | C14: 27.4 | N14: =G14+I14+K14+M14 -> 0 | O14: =N14-C14 -> -27.4 | P14: =E14+7 -> 7 | Q14: =E14+14 -> 14 | R14: =E14+28 -> 28
B15: 11 | C15: 27.4 | N15: =G15+I15+K15+M15 -> 0 | O15: =N15-C15 -> -27.4 | P15: =E15+7 -> 7 | Q15: =E15+14 -> 14 | R15: =E15+28 -> 28
B16: 12 | C16: 27.4 | N16: =G16+I16+K16+M16 -> 0 | O16: =N16-C16 -> -27.4 | P16: =E16+7 -> 7 | Q16: =E16+14 -> 14 | R16: =E16+28 -> 28
B17: 13 | C17: 27.4 | N17: =G17+I17+K17+M17 -> 0 | O17: =N17-C17 -> -27.4 | P17: =E17+7 -> 7 | Q17: =E17+14 -> 14 | R17: =E17+28 -> 28
B18: 14 | C18: 27.4 | N18: =G18+I18+K18+M18 -> 0 | O18: =N18-C18 -> -27.4 | P18: =E18+7 -> 7 | Q18: =E18+14 -> 14 | R18: =E18+28 -> 28
B19: 15 | C19: 27.4 | N19: =G19+I19+K19+M19 -> 0 | O19: =N19-C19 -> -27.4 | P19: =E19+7 -> 7 | Q19: =E19+14 -> 14 | R19: =E19+28 -> 28
... B28: 24 | C28: 27.4 | N28: =G28+I28+K28+M28 -> 0 | O28: =N28-C28 -> -27.4 | P28: =E28+7 -> 7 | Q28: =E28+14 -> 14 | R28: =E28+28 -> 28
A29: Итого | C29: =SUM(C5:D28) -> 657.6

Sheet 5
A1: ОСНОВНЫЕ БНС | C1: м3 (проект) | E1: Дата заливки | F1: ДКБС№ | G1: м3 (ДКБС) | H1: ДКБС№ | I1: м3 (ДКБС) | J1: ДКБС№ | K1: м3 (ДКБС) | L1: ДКБС№ | M1: м3 (ДКБС) | N1: Итого | O1: Разница (Проект-Факт) | P1: 7 суток (Протокол) | Q1: 14 суток (Протокол) | R1: 28 суток (Протокол) | S1: 7 суток (Протокол) Статус | T1: 14 суток (Статус) | U1: 28 суток (Протокол) Статус
A4: №ВЭУ | B4: № сваи
A5: ВЭУ-5 | B5: 1 | C5: 27.4 | E5: 46253 | N5: =G5+I5+K5+M5 -> 0 | O5: =N5-C5 -> -27.4 | P5: =E5+7 -> 46260 | Q5: =E5+14 -> 46267 | R5: =E5+28 -> 46281
B6: 2 | C6: 27.4 | N6: =G6+I6+K6+M6 -> 0 | O6: =N6-C6 -> -27.4 | P6: =E6+7 -> 7 | Q6: =E6+14 -> 14 | R6: =E6+28 -> 28
B7: 3 | C7: 27.4 | N7: =G7+I7+K7+M7 -> 0 | O7: =N7-C7 -> -27.4 | P7: =E7+7 -> 7 | Q7: =E7+14 -> 14 | R7: =E7+28 -> 28 | U7: -
B8: 4 | C8: 27.4 | N8: =G8+I8+K8+M8 -> 0 | O8: =N8-C8 -> -27.4 | P8: =E8+7 -> 7 | Q8: =E8+14 -> 14 | R8: =E8+28 -> 28
B9: 5 | C9: 27.4 | E9: 46252 | N9: =G9+I9+K9+M9 -> 0 | O9: =N9-C9 -> -27.4 | P9: =E9+7 -> 46259 | Q9: =E9+14 -> 46266 | R9: =E9+28 -> 46280
B10: 6 | C10: 27.4 | N10: =G10+I10+K10+M10 -> 0 | O10: =N10-C10 -> -27.4 | P10: =E10+7 -> 7 | Q10: =E10+14 -> 14 | R10: =E10+28 -> 28
B11: 7 | C11: 27.4 | N11: =G11+I11+K11+M11 -> 0 | O11: =N11-C11 -> -27.4 | P11: =E11+7 -> 7 | Q11: =E11+14 -> 14 | R11: =E11+28 -> 28
B12: 8 | C12: 27.4 | N12: =G12+I12+K12+M12 -> 0 | O12: =N12-C12 -> -27.4 | P12: =E12+7 -> 7 | Q12: =E12+14 -> 14 | R12: =E12+28 -> 28
B13: 9 | C13: 27.4 | N13: =G13+I13+K13+M13 -> 0 | O13: =N13-C13 -> -27.4 | P13: =E13+7 -> 7 | Q13: =E13+14 -> 14 | R13: =E13+28 -> 28
B14: 10 | C14: 27.4 | N14: =G14+I14+K14+M14 -> 0 | O14: =N14-C14 -> -27.4 | P14: =E14+7 -> 7 | Q14: =E14+14 -> 14 | R14: =E14+28 -> 28
B15: 11 | C15: 27.4 | N15: =G15+I15+K15+M15 -> 0 | O15: =N15-C15 -> -27.4 | P15: =E15+7 -> 7 | Q15: =E15+14 -> 14 | R15: =E15+28 -> 28
B16: 12 | C16: 27.4 | N16: =G16+I16+K16+M16 -> 0 | O16: =N16-C16 -> -27.4 | P16: =E16+7 -> 7 | Q16: =E16+14 -> 14 | R16: =E16+28 -> 28
B17: 13 | C17: 27.4 | N17: =G17+I17+K17+M17 -> 0 | O17: =N17-C17 -> -27.4 | P17: =E17+7 -> 7 | Q17: =E17+14 -> 14 | R17: =E17+28 -> 28
B18: 14 | C18: 27.4 | N18: =G18+I18+K18+M18 -> 0 | O18: =N18-C18 -> -27.4 | P18: =E18+7 -> 7 | Q18: =E18+14 -> 14 | R18: =E18+28 -> 28
B19: 15 | C19: 27.4 | N19: =G19+I19+K19+M19 -> 0 | O19: =N19-C19 -> -27.4 | P19: =E19+7 -> 7 | Q19: =E19+14 -> 14 | R19: =E19+28 -> 28
B20: 16 | C20: 27.4 | N20: =G20+I20+K20+M20 -> 0 | O20: =N20-C20 -> -27.4 | P20: =E20+7 -> 7 | Q20: =E20+14 -> 14 | R20: =E20+28 -> 28
B21: 17 | C21: 27.4 | E21: 46251 | N21: =G21+I21+K21+M21 -> 0 | O21: =N21-C21 -> -27.4 | P21: =E21+7 -> 46258 | Q21: =E21+14 -> 46265 | R21: =E21+28 -> 46279
B22: 18 | C22: 27.4 | N22: =G22+I22+K22+M22 -> 0 | O22: =N22-C22 -> -27.4 | P22: =E22+7 -> 7 | Q22: =E22+14 -> 14 | R22: =E22+28 -> 28
B23: 19 | C23: 27.4 | E23: 46250 | N23: =G23+I23+K23+M23 -> 0 | O23: =N23-C23 -> -27.4 | P23: =E23+7 -> 46257 | Q23: =E23+14 -> 46264 | R23: =E23+28 -> 46278
B24: 20 | C24: 27.4 | N24: =G24+I24+K24+M24 -> 0 | O24: =N24-C24 -> -27.4 | P24: =E24+7 -> 7 | Q24: =E24+14 -> 14 | R24: =E24+28 -> 28
B25: 21 | C25: 27.4 | E25: 46249 | N25: =G25+I25+K25+M25 -> 0 | O25: =N25-C25 -> -27.4 | P25: =E25+7 -> 46256 | Q25: =E25+14 -> 46263 | R25: =E25+28 -> 46277
B26: 22 | C26: 27.4 | N26: =G26+I26+K26+M26 -> 0 | O26: =N26-C26 -> -27.4 | P26: =E26+7 -> 7 | Q26: =E26+14 -> 14 | R26: =E26+28 -> 28
B27: 23 | C27: 27.4 | E27: 46252 | N27: =G27+I27+K27+M27 -> 0 | O27: =N27-C27 -> -27.4 | P27: =E27+7 -> 46259 | Q27: =E27+14 -> 46266 | R27: =E27+28 -> 46280
B28: 24 | C28: 27.4 | N28: =G28+I28+K28+M28 -> 0 | O28: =N28-C28 -> -27.4 | P28: =E28+7 -> 7 | Q28: =E28+14 -> 14 | R28: =E28+28 -> 28
A29: Итого | C29: =SUM(C5:D28) -> 657.6

Sheet 6
A1: ОСНОВНЫЕ БНС | C1: м3 (проект) | E1: Дата заливки | F1: ДКБС№ | G1: м3 (ДКБС) | H1: ДКБС№ | I1: м3 (ДКБС) | J1: ДКБС№ | K1: м3 (ДКБС) | L1: ДКБС№ | M1: м3 (ДКБС) | N1: Итого | O1: Разница (Проект-Факт) | P1: 7 суток (Протокол) | Q1: 14 суток (Протокол) | R1: 28 суток (Протокол) | S1: 7 суток (Протокол) Статус | T1: 14 суток (Статус) | U1: 28 суток (Протокол) Статус
A4: №ВЭУ | B4: № сваи
A5: ВЭУ-6 | B5: 1 | C5: 26.27 | N5: =G5+I5+K5+M5 -> 0 | O5: =N5-C5 -> -26.27 | P5: =E5+7 -> 7 | Q5: =E5+14 -> 14 | R5: =E5+28 -> 28
B6: 2 | C6: 26.27 | N6: =G6+I6+K6+M6 -> 0 | O6: =N6-C6 -> -26.27 | P6: =E6+7 -> 7 | Q6: =E6+14 -> 14 | R6: =E6+28 -> 28
B7: 3 | C7: 26.27 | N7: =G7+I7+K7+M7 -> 0 | O7: =N7-C7 -> -26.27 | P7: =E7+7 -> 7 | Q7: =E7+14 -> 14 | R7: =E7+28 -> 28 | U7: -
B8: 4 | C8: 26.27 | N8: =G8+I8+K8+M8 -> 0 | O8: =N8-C8 -> -26.27 | P8: =E8+7 -> 7 | Q8: =E8+14 -> 14 | R8: =E8+28 -> 28
B9: 5 | C9: 26.27 | N9: =G9+I9+K9+M9 -> 0 | O9: =N9-C9 -> -26.27 | P9: =E9+7 -> 7 | Q9: =E9+14 -> 14 | R9: =E9+28 -> 28
B10: 6 | C10: 26.27 | N10: =G10+I10+K10+M10 -> 0 | O10: =N10-C10 -> -26.27 | P10: =E10+7 -> 7 | Q10: =E10+14 -> 14 | R10: =E10+28 -> 28
B11: 7 | C11: 26.27 | N11: =G11+I11+K11+M11 -> 0 | O11: =N11-C11 -> -26.27 | P11: =E11+7 -> 7 | Q11: =E11+14 -> 14 | R11: =E11+28 -> 28
B12: 8 | C12: 26.27 | N12: =G12+I12+K12+M12 -> 0 | O12: =N12-C12 -> -26.27 | P12: =E12+7 -> 7 | Q12: =E12+14 -> 14 | R12: =E12+28 -> 28
B13: 9 | C13: 26.27 | N13: =G13+I13+K13+M13 -> 0 | O13: =N13-C13 -> -26.27 | P13: =E13+7 -> 7 | Q13: =E13+14 -> 14 | R13: =E13+28 -> 28
B14: 10 | C14: 26.27 | N14: =G14+I14+K14+M14 -> 0 | O14: =N14-C14 -> -26.27 | P14: =E14+7 -> 7 | Q14: =E14+14 -> 14 | R14: =E14+28 -> 28
B15: 11 | C15: 26.27 | N15: =G15+I15+K15+M15 -> 0 | O15: =N15-C15 -> -26.27 | P15: =E15+7 -> 7 | Q15: =E15+14 -> 14 | R15: =E15+28 -> 28
B16: 12 | C16: 26.27 | N16: =G16+I16+K16+M16 -> 0 | O16: =N16-C16 -> -26.27 | P16: =E16+7 -> 7 | Q16: =E16+14 -> 14 | R16: =E16+28 -> 28
B17: 13 | C17: 26.27 | N17: =G17+I17+K17+M17 -> 0 | O17: =N17-C17 -> -26.27 | P17: =E17+7 -> 7 | Q17: =E17+14 -> 14 | R17: =E17+28 -> 28
B18: 14 | C18: 26.27 | N18: =G18+I18+K18+M18 -> 0 | O18: =N18-C18 -> -26.27 | P18: =E18+7 -> 7 | Q18: =E18+14 -> 14 | R18: =E18+28 -> 28
B19: 15 | C19: 26.27 | N19: =G19+I19+K19+M19 -> 0 | O19: =N19-C19 -> -26.27 | P19: =E19+7 -> 7 | Q19: =E19+14 -> 14 | R19: =E19+28 -> 28
... B28: 24 | C28: 26.27 | N28: =G28+I28+K28+M28 -> 0 | O28: =N28-C28 -> -26.27 | P28: =E28+7 -> 7 | Q28: =E28+14 -> 14 | R28: =E28+28 -> 28
A29: Итого | C29: =SUM(C5:D28) -> 630.48

Sheet 7
A1: ОСНОВНЫЕ БНС | C1: м3 (проект) | E1: Дата заливки | F1: ДКБС№ | G1: м3 (ДКБС) | H1: ДКБС№ | I1: м3 (ДКБС) | J1: ДКБС№ | K1: м3 (ДКБС) | L1: ДКБС№ | M1: м3 (ДКБС) | N1: Итого | O1: Разница (Проект-Факт) | P1: 7 суток (Протокол) | Q1: 14 суток (Протокол) | R1: 28 суток (Протокол) | S1: 7 суток (Протокол) Статус | T1: 14 суток (Статус) | U1: 28 суток (Протокол) Статус
A4: №ВЭУ | B4: № сваи
A5: ВЭУ-7 | B5: 1 | C5: 26.27 | E5: 46250 | N5: =G5+I5+K5+M5 -> 0 | O5: =N5-C5 -> -26.27 | P5: =E5+7 -> 46257 | Q5: =E5+14 -> 46264 | R5: =E5+28 -> 46278
B6: 2 | C6: 26.27 | N6: =G6+I6+K6+M6 -> 0 | O6: =N6-C6 -> -26.27 | P6: =E6+7 -> 7 | Q6: =E6+14 -> 14 | R6: =E6+28 -> 28
B7: 3 | C7: 26.27 | E7: 46245 | F7: 57/32 | G7: 9 | H7: 57/31 | I7: 9 | J7: 57/30 | K7: 9 | N7: =G7+I7+K7+M7 -> 27 | O7: =N7-C7 -> 0.73 | P7: =E7+7 -> 46252 | Q7: =E7+14 -> 46259 | R7: =E7+28 -> 46273 | U7: -
B8: 4 | C8: 26.27 | E8: 46247 | F8: 59/35 | G8: 9 | H8: 59/36 | I8: 9 | J8: 59/37 | K8: 9 | N8: =G8+I8+K8+M8 -> 27 | O8: =N8-C8 -> 0.73 | P8: =E8+7 -> 46254 | Q8: =E8+14 -> 46261 | R8: =E8+28 -> 46275
B9: 5 | C9: 26.27 | E9: 46245 | F9: 57/20 | G9: 9 | H9: 57/23 | I9: 9 | J9: 57/22 | K9: 9 | N9: =G9+I9+K9+M9 -> 27 | O9: =N9-C9 -> 0.73 | P9: =E9+7 -> 46252 | Q9: =E9+14 -> 46259 | R9: =E9+28 -> 46273
B10: 6 | C10: 26.27 | E10: 46247 | F10: 59/22 | G10: 9 | H10: 59/23 | I10: 9 | J10: 59/24 | K10: 9 | N10: =G10+I10+K10+M10 -> 27 | O10: =N10-C10 -> 0.73 | P10: =E10+7 -> 46254 | Q10: =E10+14 -> 46261 | R10: =E10+28 -> 46275
B11: 7 | C11: 26.27 | E11: 46245 | F11: 57/3 | G11: 9 | H11: 57/2 | I11: 9 | J11: 57/1 | K11: 9 | N11: =G11+I11+K11+M11 -> 27 | O11: =N11-C11 -> 0.73 | P11: =E11+7 -> 46252 | Q11: =E11+14 -> 46259 | R11: =E11+28 -> 46273
B12: 8 | C12: 26.27 | E12: 46247 | F12: 59/7 | G12: 9 | H12: 59/8 | I12: 9 | J12: 59/9 | K12: 9 | N12: =G12+I12+K12+M12 -> 27 | O12: =N12-C12 -> 0.73 | P12: =E12+7 -> 46254 | Q12: =E12+14 -> 46261 | R12: =E12+28 -> 46275
B13: 9 | C13: 26.27 | E13: 46244 | F13: 56/22 | G13: 9 | H13: 56/23 | I13: 9 | J13: 56/24 | K13: 9 | N13: =G13+I13+K13+M13 -> 27 | O13: =N13-C13 -> 0.73 | P13: =E13+7 -> 46251 | Q13: =E13+14 -> 46258 | R13: =E13+28 -> 46272
B14: 10 | C14: 26.27 | E14: 46250 | N14: =G14+I14+K14+M14 -> 0 | O14: =N14-C14 -> -26.27 | P14: =E14+7 -> 46257 | Q14: =E14+14 -> 46264 | R14: =E14+28 -> 46278
B15: 11 | C15: 26.27 | E15: 46244 | F15: 56/4 | G15: 9 | H15: 56/5 | I15: 9 | J15: 56/6 | K15: 9 | N15: =G15+I15+K15+M15 -> 27 | O15: =N15-C15 -> 0.73 | P15: =E15+7 -> 46251 | Q15: =E15+14 -> 46258 | R15: =E15+28 -> 46272
B16: 12 | C16: 26.27 | E16: 46250 | N16: =G16+I16+K16+M16 -> 0 | O16: =N16-C16 -> -26.27 | P16: =E16+7 -> 46257 | Q16: =E16+14 -> 46264 | R16: =E16+28 -> 46278
B17: 13 | C17: 26.27 | E17: 46243 | F17: 55/20 | G17: 9 | H17: 55/19 | I17: 9 | J17: 55/18 | K17: 9 | N17: =G17+I17+K17+M17 -> 27 | O17: =N17-C17 -> 0.73 | P17: =E17+7 -> 46250 | Q17: =E17+14 -> 46257 | R17: =E17+28 -> 46271
B18: 14 | C18: 26.27 | N18: =G18+I18+K18+M18 -> 0 | O18: =N18-C18 -> -26.27 | P18: =E18+7 -> 7 | Q18: =E18+14 -> 14 | R18: =E18+28 -> 28
B19: 15 | C19: 26.27 | E19: 46246 | F19: 58/6 | G19: 9 | H19: 58/5 | I19: 9 | J19: 58/4 | K19: 9 | N19: =G19+I19+K19+M19 -> 27 | O19: =N19-C19 -> 0.73 | P19: =E19+7 -> 46253 | Q19: =E19+14 -> 46260 | R19: =E19+28 -> 46274
B20: 16 | C20: 26.27 | E20: 46249 | N20: =G20+I20+K20+M20 -> 0 | O20: =N20-C20 -> -26.27 | P20: =E20+7 -> 46256 | Q20: =E20+14 -> 46263 | R20: =E20+28 -> 46277
B21: 17 | C21: 26.27 | E21: 46246 | F21: 58/18 | G21: 9 | H21: 58/17 | I21: 9 | J21: 58/16 | K21: 9 | N21: =G21+I21+K21+M21 -> 27 | O21: =N21-C21 -> 0.73 | P21: =E21+7 -> 46253 | Q21: =E21+14 -> 46260 | R21: =E21+28 -> 46274
B22: 18 | C22: 26.27 | E22: 46249 | N22: =G22+I22+K22+M22 -> 0 | O22: =N22-C22 -> -26.27 | P22: =E22+7 -> 46256 | Q22: =E22+14 -> 46263 | R22: =E22+28 -> 46277
B23: 19 | C23: 26.27 | E23: 46246 | F23: 58/30 | G23: 9 | H23: 58/29 | I23: 9 | J23: 58/28 | K23: 9 | N23: =G23+I23+K23+M23 -> 27 | O23: =N23-C23 -> 0.73 | P23: =E23+7 -> 46253 | Q23: =E23+14 -> 46260 | R23: =E23+28 -> 46274
B24: 20 | C24: 26.27 | E24: 46251 | N24: =G24+I24+K24+M24 -> 0 | O24: =N24-C24 -> -26.27 | P24: =E24+7 -> 46258 | Q24: =E24+14 -> 46265 | R24: =E24+28 -> 46279
B25: 21 | C25: 26.27 | E25: 46248 | F25: 59/44 | G25: 9 | N25: =G25+I25+K25+M25 -> 9 | O25: =N25-C25 -> -17.27 | P25: =E25+7 -> 46255 | Q25: =E25+14 -> 46262 | R25: =E25+28 -> 46276
B26: 22 | C26: 26.27 | E26: 46250 | N26: =G26+I26+K26+M26 -> 0 | O26: =N26-C26 -> -26.27 | P26: =E26+7 -> 46257 | Q26: =E26+14 -> 46264 | R26: =E26+28 -> 46278
B27: 23 | C27: 26.27 | E27: 46249 | N27: =G27+I27+K27+M27 -> 0 | O27: =N27-C27 -> -26.27 | P27: =E27+7 -> 46256 | Q27: =E27+14 -> 46263 | R27: =E27+28 -> 46277
B28: 24 | C28: 26.27 | N28: =G28+I28+K28+M28 -> 0 | O28: =N28-C28 -> -26.27 | P28: =E28+7 -> 7 | Q28: =E28+14 -> 14 | R28: =E28+28 -> 28
A29: Итого | C29: =SUM(C5:D28) -> 630.48

Sheet 8
A1: ОСНОВНЫЕ БНС | C1: м3 (проект) | E1: Дата заливки | F1: ДКБС№ | G1: м3 (ДКБС) | H1: ДКБС№ | I1: м3 (ДКБС) | J1: ДКБС№ | K1: м3 (ДКБС) | L1: ДКБС№ | M1: м3 (ДКБС) | N1: Итого | O1: Разница (Проект-Факт) | P1: 7 суток (Протокол) | Q1: 14 суток (Протокол) | R1: 28 суток (Протокол) | S1: 7 суток (Протокол) Статус | T1: 14 суток (Статус) | U1: 28 суток (Протокол) Статус
A4: №ВЭУ | B4: № сваи
A5: ВЭУ-8 | B5: 1 | C5: 27.4 | N5: =G5+I5+K5+M5 -> 0 | O5: =N5-C5 -> -27.4 | P5: =E5+7 -> 7 | Q5: =E5+14 -> 14 | R5: =E5+28 -> 28
B6: 2 | C6: 27.4 | E6: 46252 | N6: =G6+I6+K6+M6 -> 0 | O6: =N6-C6 -> -27.4 | P6: =E6+7 -> 46259 | Q6: =E6+14 -> 46266 | R6: =E6+28 -> 46280
B7: 3 | C7: 27.4 | N7: =G7+I7+K7+M7 -> 0 | O7: =N7-C7 -> -27.4 | P7: =E7+7 -> 7 | Q7: =E7+14 -> 14 | R7: =E7+28 -> 28 | U7: -
B8: 4 | C8: 27.4 | N8: =G8+I8+K8+M8 -> 0 | O8: =N8-C8 -> -27.4 | P8: =E8+7 -> 7 | Q8: =E8+14 -> 14 | R8: =E8+28 -> 28
B9: 5 | C9: 27.4 | N9: =G9+I9+K9+M9 -> 0 | O9: =N9-C9 -> -27.4 | P9: =E9+7 -> 7 | Q9: =E9+14 -> 14 | R9: =E9+28 -> 28
B10: 6 | C10: 27.4 | N10: =G10+I10+K10+M10 -> 0 | O10: =N10-C10 -> -27.4 | P10: =E10+7 -> 7 | Q10: =E10+14 -> 14 | R10: =E10+28 -> 28
B11: 7 | C11: 27.4 | N11: =G11+I11+K11+M11 -> 0 | O11: =N11-C11 -> -27.4 | P11: =E11+7 -> 7 | Q11: =E11+14 -> 14 | R11: =E11+28 -> 28
B12: 8 | C12: 27.4 | N12: =G12+I12+K12+M12 -> 0 | O12: =N12-C12 -> -27.4 | P12: =E12+7 -> 7 | Q12: =E12+14 -> 14 | R12: =E12+28 -> 28
B13: 9 | C13: 27.4 | N13: =G13+I13+K13+M13 -> 0 | O13: =N13-C13 -> -27.4 | P13: =E13+7 -> 7 | Q13: =E13+14 -> 14 | R13: =E13+28 -> 28
B14: 10 | C14: 27.4 | N14: =G14+I14+K14+M14 -> 0 | O14: =N14-C14 -> -27.4 | P14: =E14+7 -> 7 | Q14: =E14+14 -> 14 | R14: =E14+28 -> 28
B15: 11 | C15: 27.4 | E15: 46252 | N15: =G15+I15+K15+M15 -> 0 | O15: =N15-C15 -> -27.4 | P15: =E15+7 -> 46259 | Q15: =E15+14 -> 46266 | R15: =E15+28 -> 46280
B16: 12 | C16: 27.4 | N16: =G16+I16+K16+M16 -> 0 | O16: =N16-C16 -> -27.4 | P16: =E16+7 -> 7 | Q16: =E16+14 -> 14 | R16: =E16+28 -> 28
B17: 13 | C17: 27.4 | E17: 46253 | N17: =G17+I17+K17+M17 -> 0 | O17: =N17-C17 -> -27.4 | P17: =E17+7 -> 46260 | Q17: =E17+14 -> 46267 | R17: =E17+28 -> 46281
B18: 14 | C18: 27.4 | N18: =G18+I18+K18+M18 -> 0 | O18: =N18-C18 -> -27.4 | P18: =E18+7 -> 7 | Q18: =E18+14 -> 14 | R18: =E18+28 -> 28
B19: 15 | C19: 27.4 | E19: 46251 | N19: =G19+I19+K19+M19 -> 0 | O19: =N19-C19 -> -27.4 | P19: =E19+7 -> 46258 | Q19: =E19+14 -> 46265 | R19: =E19+28 -> 46279
B20: 16 | C20: 27.4 | N20: =G20+I20+K20+M20 -> 0 | O20: =N20-C20 -> -27.4 | P20: =E20+7 -> 7 | Q20: =E20+14 -> 14 | R20: =E20+28 -> 28
B21: 17 | C21: 27.4 | N21: =G21+I21+K21+M21 -> 0 | O21: =N21-C21 -> -27.4 | P21: =E21+7 -> 7 | Q21: =E21+14 -> 14 | R21: =E21+28 -> 28
B22: 18 | C22: 27.4 | N22: =G22+I22+K22+M22 -> 0 | O22: =N22-C22 -> -27.4 | P22: =E22+7 -> 7 | Q22: =E22+14 -> 14 | R22: =E22+28 -> 28
B23: 19 | C23: 27.4 | N23: =G23+I23+K23+M23 -> 0 | O23: =N23-C23 -> -27.4 | P23: =E23+7 -> 7 | Q23: =E23+14 -> 14 | R23: =E23+28 -> 28
B24: 20 | C24: 27.4 | N24: =G24+I24+K24+M24 -> 0 | O24: =N24-C24 -> -27.4 | P24: =E24+7 -> 7 | Q24: =E24+14 -> 14 | R24: =E24+28 -> 28
B25: 21 | C25: 27.4 | N25: =G25+I25+K25+M25 -> 0 | O25: =N25-C25 -> -27.4 | P25: =E25+7 -> 7 | Q25: =E25+14 -> 14 | R25: =E25+28 -> 28
B26: 22 | C26: 27.4 | N26: =G26+I26+K26+M26 -> 0 | O26: =N26-C26 -> -27.4 | P26: =E26+7 -> 7 | Q26: =E26+14 -> 14 | R26: =E26+28 -> 28
B27: 23 | C27: 27.4 | E27: 46252 | N27: =G27+I27+K27+M27 -> 0 | O27: =N27-C27 -> -27.4 | P27: =E27+7 -> 46259 | Q27: =E27+14 -> 46266 | R27: =E27+28 -> 46280
B28: 24 | C28: 27.4 | N28: =G28+I28+K28+M28 -> 0 | O28: =N28-C28 -> -27.4 | P28: =E28+7 -> 7 | Q28: =E28+14 -> 14 | R28: =E28+28 -> 28
A29: Итого | C29: =SUM(C5:D28) -> 657.6

Sheet 9
A1: ОСНОВНЫЕ БНС | C1: м3 (проект) | E1: Дата заливки | F1: ДКБС№ | G1: м3 (ДКБС) | H1: ДКБС№ | I1: м3 (ДКБС) | J1: ДКБС№ | K1: м3 (ДКБС) | L1: ДКБС№ | M1: м3 (ДКБС) | N1: Итого | O1: Разница (Проект-Факт) | P1: 7 суток (Протокол) | Q1: 14 суток (Протокол) | R1: 28 суток (Протокол) | S1: 7 суток (Протокол) Статус | T1: 14 суток (Статус) | U1: 28 суток (Протокол) Статус
A4: №ВЭУ | B4: № сваи
A5: ВЭУ-9 | B5: 1 | C5: 27.4 | E5: 46248 | N5: =G5+I5+K5+M5 -> 0 | O5: =N5-C5 -> -27.4 | P5: =E5+7 -> 46255 | Q5: =E5+14 -> 46262 | R5: =E5+28 -> 46276
B6: 2 | C6: 27.4 | E6: 46240 | F6: 52/3 | G6: 9 | H6: 52/2 | I6: 9.5 | J6: 52/1 | K6: 9.5 | N6: =G6+I6+K6+M6 -> 28 | O6: =N6-C6 -> 0.6 | P6: =E6+7 -> 46247 | Q6: =E6+14 -> 46254 | R6: =E6+28 -> 46268 | S6: +
B7: 3 | C7: 27.4 | E7: 46244 | F7: 56/10 | G7: 9.5 | H7: 56/11 | I7: 9.5 | J7: 56/12 | K7: 9 | N7: =G7+I7+K7+M7 -> 28 | O7: =N7-C7 -> 0.6 | P7: =E7+7 -> 46251 | Q7: =E7+14 -> 46258 | R7: =E7+28 -> 46272 | U7: -
B8: 4 | C8: 27.4 | E8: 46241 | F8: 53/25 | G8: 9 | H8: 53/23 | I8: 9.5 | J8: 53/22 | K8: 9.5 | N8: =G8+I8+K8+M8 -> 28 | O8: =N8-C8 -> 0.6 | P8: =E8+7 -> 46248 | Q8: =E8+14 -> 46255 | R8: =E8+28 -> 46269 | S8: +
B9: 5 | C9: 27.4 | E9: 46245 | F9: 57/12 | G9: 9 | H9: 57/11 | I9: 9.5 | J9: 57/10 | K9: 9.5 | N9: =G9+I9+K9+M9 -> 28 | O9: =N9-C9 -> 0.6 | P9: =E9+7 -> 46252 | Q9: =E9+14 -> 46259 | R9: =E9+28 -> 46273
B10: 6 | C10: 27.4 | E10: 46242 | F10: 54/23 | G10: 9 | H10: 54/22 | I10: 9.5 | J10: 54/21 | K10: 9.5 | N10: =G10+I10+K10+M10 -> 28 | O10: =N10-C10 -> 0.6 | P10: =E10+7 -> 46249 | Q10: =E10+14 -> 46256 | R10: =E10+28 -> 46270
B11: 7 | C11: 27.4 | E11: 46246 | F11: 59/25 | G11: 9.5 | H11: 59/26 | I11: 9.5 | J11: 59/27 | K11: 9 | N11: =G11+I11+K11+M11 -> 28 | O11: =N11-C11 -> 0.6 | P11: =E11+7 -> 46253 | Q11: =E11+14 -> 46260 | R11: =E11+28 -> 46274
B12: 8 | C12: 27.4 | E12: 46245 | F12: 57/37 | G12: 9 | H12: 57/36 | I12: 9 | J12: 57/35 | K12: 9.5 | N12: =G12+I12+K12+M12 -> 27.5 | O12: =N12-C12 -> 0.1 | P12: =E12+7 -> 46252 | Q12: =E12+14 -> 46259 | R12: =E12+28 -> 46273
B13: 9 | C13: 27.4 | E13: 46246 | F13: 58/27 | G13: 9 | H13: 58/26 | I13: 9.5 | J13: 58/25 | K13: 9.5 | N13: =G13+I13+K13+M13 -> 28 | O13: =N13-C13 -> 0.6 | P13: =E13+7 -> 46253 | Q13: =E13+14 -> 46260 | R13: =E13+28 -> 46274
B14: 10 | C14: 27.4 | E14: 46249 | N14: =G14+I14+K14+M14 -> 0 | O14: =N14-C14 -> -27.4 | P14: =E14+7 -> 46256 | Q14: =E14+14 -> 46263 | R14: =E14+28 -> 46277
B15: 11 | C15: 27.4 | E15: 46243 | F15: 55/33 | G15: 9 | H15: 55/32 | I15: 9.5 | J15: 55/31 | K15: 9.5 | N15: =G15+I15+K15+M15 -> 28 | O15: =N15-C15 -> 0.6 | P15: =E15+7 -> 46250 | Q15: =E15+14 -> 46257 | R15: =E15+28 -> 46271
B16: 12 | C16: 27.4 | E16: 46248 | N16: =G16+I16+K16+M16 -> 0 | O16: =N16-C16 -> -27.4 | P16: =E16+7 -> 46255 | Q16: =E16+14 -> 46262 | R16: =E16+28 -> 46276
B17: 13 | C17: 27.4 | E17: 46239 | F17: 51/24 | G17: 9 | H17: 51/23 | I17: 9.5 | J17: 51/22 | K17: 9.5 | N17: =G17+I17+K17+M17 -> 28 | O17: =N17-C17 -> 0.6 | P17: =E17+7 -> 46246 | Q17: =E17+14 -> 46253 | R17: =E17+28 -> 46267 | S17: +
B18: 14 | C18: 27.4 | E18: 46247 | F18: 59/41 | G18: 9.5 | H18: 59/42 | I18: 9.5 | J18: 59/43 | K18: 9 | N18: =G18+I18+K18+M18 -> 28 | O18: =N18-C18 -> 0.6 | P18: =E18+7 -> 46254 | Q18: =E18+14 -> 46261 | R18: =E18+28 -> 46275
B19: 15 | C19: 27.4 | E19: 46241 | F19: 53/9 | G19: 9 | H19: 53/8 | I19: 9.5 | J19: 53/7 | K19: 9.5 | N19: =G19+I19+K19+M19 -> 28 | O19: =N19-C19 -> 0.6 | P19: =E19+7 -> 46248 | Q19: =E19+14 -> 46255 | R19: =E19+28 -> 46269 | S19: +
B20: 16 | C20: 27.4 | E20: 46244 | F20: 56/28 | G20: 9.5 | H20: 56/29 | I20: 9.5 | J20: 56/30 | K20: 9 | N20: =G20+I20+K20+M20 -> 28 | O20: =N20-C20 -> 0.6 | P20: =E20+7 -> 46251 | Q20: =E20+14 -> 46258 | R20: =E20+28 -> 46272
B21: 17 | C21: 27.4 | E21: 46242 | F21: 54/4 | G21: 9.5 | H21: 54/5 | I21: 9.5 | J21: 54/6 | K21: 9 | N21: =G21+I21+K21+M21 -> 28 | O21: =N21-C21 -> 0.6 | P21: =E21+7 -> 46249 | Q21: =E21+14 -> 46256 | R21: =E21+28 -> 46270
B22: 18 | C22: 27.4 | E22: 46245 | F22: 57/26 | G22: 9 | H22: 57/25 | I22: 9.5 | J22: 57/24 | K22: 9.5 | N22: =G22+I22+K22+M22 -> 28 | O22: =N22-C22 -> 0.6 | P22: =E22+7 -> 46252 | Q22: =E22+14 -> 46259 | R22: =E22+28 -> 46273
B23: 19 | C23: 27.4 | E23: 46243 | F23: 55/8 | G23: 9 | H23: 55/7 | I23: 9.5 | J23: 55/6 | K23: 9.5 | N23: =G23+I23+K23+M23 -> 28 | O23: =N23-C23 -> 0.6 | P23: =E23+7 -> 46250 | Q23: =E23+14 -> 46257 | R23: =E23+28 -> 46271
B24: 20 | C24: 27.4 | E24: 46246 | F24: 58/15 | G24: 9 | H24: 58/14 | I24: 9.5 | J24: 58/13 | K24: 9.5 | N24: =G24+I24+K24+M24 -> 28 | O24: =N24-C24 -> 0.6 | P24: =E24+7 -> 46253 | Q24: =E24+14 -> 46260 | R24: =E24+28 -> 46274
B25: 21 | C25: 27.4 | E25: 46247 | F25: 59/14 | G25: 9.5 | H25: 59/13 | I25: 9.5 | J25: 59/15 | K25: 9 | N25: =G25+I25+K25+M25 -> 28 | O25: =N25-C25 -> 0.6 | P25: =E25+7 -> 46254 | Q25: =E25+14 -> 46261 | R25: =E25+28 -> 46275
